Workbook
Name IQ_CH: 110000
Name IQ_CQ: 5000
Name IQ_CY: 10000
Name IQ_DAILY: 500000
Name IQ_FH: 100000
Name IQ_FQ: 500
Name IQ_FY: 1000
Name IQ_LTM: 2000
Name IQ_MONTH: 15000
Name IQ_NTM: 6000
Name IQ_WEEK: 50000
Name IQ_YTD: 3000

Sheet Data
A1: End Date | B1: 45973
A2: Span | B2: 5
A3: Start Date | B3: 44147
A4: Frequency | B4: M
B5: ConocoPhillips | C5: Exxon Mobil Corporation | D5: Chevron Corporation | E5: EOG Resources, Inc. | F5: BP p.l.c. | G5: Devon Energy Corporation | H5: PE-From Ifind | N5: EV/EBITDA-From Ifind | T5: PB | Z5: PS | AF5: Oil Price | AG5: Copper-Price Per Pound | AH5: Energy Sector Index | AI5: SPX | AJ5: Market Cap in Million | AP5: EV without Cash in Million
B6: COP | C6: XOM | D6: CVX | E6: EOG | F6: BP | G6: DVN | H6: COP | I6: XOM | J6: CVX | K6: EOG | L6: BP | M6: DVN | N6: COP | O6: XOM | P6: CVX | Q6: EOG | R6: BP | S6: DVN | T6: COP | U6: XOM | V6: CVX | W6: EOG | X6: BP | Y6: DVN | Z6: COP | AA6: XOM | AB6: CVX | AC6: EOG | AD6: BP | AE6: DVN | AF6: ^cl | AG6: ^HG | AH6: ^SP500-10 | AI6: IQT46156516 | AJ6: COP | AK6: XOM | AL6: CVX | AM6: EOG | AN6: BP | AO6: DVN | AP6: COP | AQ6: XOM | AR6: CVX | AS6: EOG | AT6: BP | AU6: DVN
A7: IQ_PRICEDATE | B7: IQ_CLOSEPRICE_ADJ | AF7: IQ_Closeprice | AG7: IQ_Closeprice | AH7: IQ_Closeprice | AI7: IQ_Closeprice
A8: IQ_PRICEDATE | B8: IQ_CLOSEPRICE_ADJ | C8: IQ_CLOSEPRICE_ADJ | D8: IQ_CLOSEPRICE_ADJ | E8: IQ_CLOSEPRICE_ADJ | F8: IQ_CLOSEPRICE_ADJ | G8: IQ_CLOSEPRICE_ADJ | AF8: IQ_Closeprice | AG8: IQ_Closeprice | AH8: IQ_Closeprice | AI8: IQ_Closeprice
A9: 45961 | B9: 88.86 | C9: 113.36841 | D9: 157.72 | E9: 105.84 | F9: 34.65422 | G9: 32.49 | H9: 12.413059 | I9: 16.10106 | J9: 24.872543 | K9: 10.384922 | L9: 60.486287 | M9: 7.495762 | N9: 5.5016082 | O9: 7.0835763 | P9: 7.9742035 | Q9: 4.9416416 | R9: 4.8598349 | S9: 3.7508836 | T9: 1.6913255 | U9: 1.8509104 | V9: 1.6728172 | W9: 1.8962728 | X9: 1.5764402 | Y9: 1.3277509 | Z9: 1.7682113 | AA9: 1.4467268 | AB9: 1.6337385 | AC9: 2.5434528 | AD9: 0.47600085 | AE9: 1.1666272 | AF9: 60.98 | AG9: 5.089 | AH9: 674.73686 | AI9: 13085.098 | AJ9: 109805.92 | AK9: 482275.06 | AL9: 317572.63 | AM9: 57428.621 | AN9: 91818.183 | AO9: 20380.977 | AP9: 128027.92 | AQ9: 519304.06 | AR9: 357148.63 | AS9: 61592.621 | AT9: 136498.18 | AU9: 27493.977
A10: 45930 | B10: 94.59 | C10: 111.77237 | D10: 155.29 | E10: 111.05368 | F10: 33.99329 | G10: 35.06 | H10: 13.213496 | I10: 15.874384 | J10: 24.48933 | K10: 11.025176 | L10: 59.656111 | M10: 8.1106068 | N10: 5.8058781 | O10: 6.9909621 | P10: 7.8649587 | Q10: 5.2257081 | R10: 4.8149669 | S10: 3.978955 | T10: 1.800388 | U10: 1.8248526 | V10: 1.647044 | W10: 2.0131823 | X10: 1.5548035 | Y10: 1.4366606 | Z10: 1.8822317 | AA10: 1.4263593 | AB10: 1.6085674 | AC10: 2.7002624 | AD10: 0.46946772 | AE10: 1.2623205 | AF10: 61.96 | AG10: 4.8565 | AH10: 682.82225 | AI10: 12788.463 | AJ10: 116886.59 | AK10: 475485.42 | AL10: 312679.77 | AM10: 60969.226 | AN10: 90557.976 | AO10: 22052.74 | AP10: 135108.59 | AQ10: 512514.42 | AR10: 352255.77 | AS10: 65133.226 | AT10: 135237.98 | AU10: 29165.74
A11: 45898 | B11: 98.97 | C11: 113.29902 | D11: 160.6 | E11: 123.6329 | F11: 34.75287 | G11: 35.85082 | H11: 13.457574 | I11: 15.710027 | J11: 20.232958 | K11: 11.88955 | L11: 164.9248 | M11: 8.0577637 | N11: 6.112149 | O11: 7.082873 | P11: 6.7822241 | Q11: 5.3891927 | R11: 4.9372187 | S11: 4.1292333 | T11: 1.8850702 | U11: 1.8555198 | V11: 1.8953759 | W11: 2.3309015 | X11: 1.5673981 | Y11: 1.5216653 | Z11: 2.0539002 | AA11: 1.4412251 | AB11: 1.4207726 | AC11: 3.002639 | AD11: 0.48367059 | AE11: 1.3352141 | AF11: 64.01 | AG11: 4.5185 | AH11: 686.39366 | AI11: 12342.326 | AJ11: 123607.82 | AK11: 487246.5 | AL11: 277515.25 | AM11: 68150.898 | AN11: 92852.662 | AO11: 22916.28 | AP11: 142235.82 | AQ11: 519252.5 | AR11: 303762.25 | AS11: 67170.898 | AT11: 138671.66 | AU11: 30267.28
A12: 45869 | B12: 94.55992 | C12: 109.65165 | D12: 149.97052 | E12: 118.87855 | F12: 31.26212 | G12: 32.9907 | H12: 12.96398 | I12: 15.345765 | J12: 19.104146 | K12: 11.432332 | L12: 150.50617 | M12: 7.4149283 | N12: 5.9173289 | O12: 6.9287678 | P12: 6.4365335 | Q12: 5.1789257 | R12: 4.6481992 | S12: 3.8798166 | T12: 1.81593 | U12: 1.8124965 | V12: 1.7896314 | W12: 2.2412658 | X12: 1.4303675 | Y12: 1.4002693 | Z12: 1.9785677 | AA12: 1.407808 | AB12: 1.3415066 | AC12: 2.8871714 | AD12: 0.44138545 | AE12: 1.2286929 | AF12: 69.26 | AG12: 4.3545 | AH12: 666.90745 | AI12: 12101.39 | AJ12: 119074.16 | AK12: 475948.9 | AL12: 262032.46 | AM12: 65530.13 | AN12: 84734.972 | AO12: 21088.056 | AP12: 137702.16 | AQ12: 507954.9 | AR12: 288279.46 | AS12: 64550.13 | AT12: 130553.97 | AU12: 28439.056
A13: 45838 | B13: 89.00574 | C13: 105.88004 | D13: 141.61355 | E13: 117.50014 | F13: 29.10342 | G13: 31.59043 | H13: 12.202513 | I13: 14.817928 | J13: 18.039585 | K13: 11.393207 | L13: 140.88483 | M13: 7.1136287 | N13: 5.6167798 | O13: 6.7054607 | P13: 6.1105194 | Q13: 5.1609325 | R13: 4.4553409 | S13: 3.7629141 | T13: 1.7092674 | U13: 1.7501534 | V13: 1.6899058 | W13: 2.2335954 | X13: 1.3389291 | Y13: 1.3433705 | Z13: 1.8623522 | AA13: 1.3593846 | AB13: 1.2667524 | AC13: 2.8772905 | AD13: 0.41316921 | AE13: 1.178766 | AF13: 65.11 | AG13: 5.0825 | AH13: 648.68124 | AI13: 11838.458 | AJ13: 112080.08 | AK13: 459578.03 | AL13: 247430.94 | AM13: 65305.862 | AN13: 79318.159 | AO13: 20231.16 | AP13: 130708.08 | AQ13: 491584.03 | AR13: 273677.94 | AS13: 64325.862 | AT13: 125137.16 | AU13: 27582.16
A14: 45807 | B14: 84.65166 | C14: 100.47799 | D14: 135.195 | E14: 106.65488 | F14: 28.29635 | G14: 29.84104 | H14: 11.290652 | I14: 13.290207 | J14: 15.244703 | K14: 9.7508797 | L14: -64.707795 | M14: 6.9666354 | N14: 5.3810191 | O14: 6.3902696 | P14: 5.9080791 | Q14: 4.6053511 | R14: 4.3413257 | S14: 3.7249585 | T14: 1.6515941 | U14: 1.6781214 | V14: 1.599609 | W14: 2.0075923 | X14: 1.3282799 | Y14: 1.3358505 | Z14: 1.808498 | AA14: 1.2609717 | AB14: 1.1836818 | AC14: 2.5493072 | AD14: 0.40159241 | AE14: 1.1568198 | AF14: 60.79 | AG14: 4.6775 | AH14: 619.34031 | AI14: 11269.579 | AJ14: 107746.7 | AK14: 440876.05 | AL14: 238732.05 | AM14: 59256.096 | AN14: 77325.815 | AO14: 19429.946 | AP14: 125221.7 | AQ14: 468477.05 | AR14: 264611.05 | AS14: 57401.096 | AT14: 121934.81 | AU14: 27303.946
A15: 45777 | B15: 87.6449 | C15: 102.80186 | D15: 132.94275 | E15: 108.38383 | F15: 26.28041 | G15: 29.98897 | H15: 11.789372 | I15: 13.722821 | J15: 15.17333 | K15: 9.9089486 | L15: -61.061032 | M15: 7.0011692 | N15: 5.5855349 | O15: 6.586026 | P15: 5.8831239 | Q15: 4.6824198 | R15: 4.1861692 | S15: 3.7380984 | T15: 1.7245468 | U15: 1.7327465 | V15: 1.59212 | W15: 2.0401369 | X15: 1.2534215 | Y15: 1.3424724 | Z15: 1.8883813 | AA15: 1.302018 | AB15: 1.1781401 | AC15: 2.5906333 | AD15: 0.37895971 | AE15: 1.1625542 | AF15: 58.21 | AG15: 4.609 | AH15: 617.46879 | AI15: 10606.485 | AJ15: 112505.98 | AK15: 455227.15 | AL15: 237614.35 | AM15: 60216.681 | AN15: 72967.934 | AO15: 19526.261 | AP15: 129980.98 | AQ15: 482828.15 | AR15: 263493.35 | AS15: 58361.681 | AT15: 117576.93 | AU15: 27400.261
A16: 45747 | B16: 103.28172 | C16: 115.74577 | D16: 163.45725 | E16: 124.83511 | F16: 32.33849 | G16: 36.88219 | H16: 13.892728 | I16: 15.450678 | J16: 18.656082 | K16: 11.632181 | L16: -75.929794 | M16: 8.6359269 | N16: 6.4480813 | O16: 7.3678758 | P16: 7.1008582 | Q16: 5.5226063 | R16: 4.8187811 | S16: 4.3601091 | T16: 2.0322251 | U16: 1.9509186 | V16: 1.957561 | W16: 2.3949304 | X16: 1.5586379 | Y16: 1.6559367 | Z16: 2.2252896 | AA16: 1.4659566 | AB16: 1.4485598 | AC16: 3.0411618 | AD16: 0.47123888 | AE16: 1.4340081 | AF16: 71.48 | AG16: 5.034 | AH16: 715.75121 | AI16: 10681.621 | AJ16: 132578.3 | AK16: 512545.34 | AL16: 292154.24 | AM16: 70688.765 | AN16: 90736.104 | AO16: 24085.6 | AP16: 150053.3 | AQ16: 540146.34 | AR16: 318033.24 | AS16: 68833.765 | AT16: 135345.1 | AU16: 31959.6
A17: 45716 | B17: 97.50888 | C17: 108.34925 | D17: 154.98589 | E17: 123.56962 | F17: 31.69727 | G17: 35.46483 | H17: 13.632114 | I17: 14.297356 | J17: 15.812589 | K17: 10.981635 | L17: 231.97251 | M17: 8.1310204 | N17: 6.220012 | O17: 6.9173377 | P17: 6.6505568 | Q17: 5.4537394 | R17: 4.550024 | S17: 4.3317572 | T17: 1.9450105 | U17: 1.8260365 | V17: 1.8334415 | W17: 2.3956733 | X17: 1.491772 | Y17: 1.6216046 | Z17: 2.2128579 | AA17: 1.3774474 | AB17: 1.3771063 | AC17: 2.9671453 | AD17: 0.45410255 | AE17: 1.4747039 | AF17: 69.76 | AG17: 4.548 | AH17: 689.88108 | AI17: 11323.729 | AJ17: 126028.9 | AK17: 481534.94 | AL17: 279266.14 | AM17: 70315.408 | AN17: 88381.525 | AO17: 23506.78 | AP17: 144745.9 | AQ17: 507116.94 | AR17: 297865.14 | AS17: 67975.408 | AT17: 127796.53 | AU17: 31751.78
A18: 45688 | B18: 96.41181 | C18: 103.048 | D18: 144.17282 | E18: 122.45016 | F18: 29.31827 | G18: 33.38903 | H18: 13.601875 | I18: 13.763381 | J18: 14.943601 | K18: 10.946627 | L18: 218.08155 | M18: 7.6786925 | N18: 6.2079986 | O18: 6.672023 | P18: 6.3078937 | Q18: 5.4357553 | R18: 4.3615933 | S18: 4.1533561 | T18: 1.940696 | U18: 1.757838 | V18: 1.7326839 | W18: 2.3880363 | X18: 1.4024419 | Y18: 1.5313949 | Z18: 2.2079493 | AA18: 1.3260028 | AB18: 1.3014268 | AC18: 2.9576865 | AD18: 0.42691003 | AE18: 1.3926662 | AF18: 72.53 | AG18: 4.279 | AH18: 667.9538 | AI18: 11477.597 | AJ18: 125749.34 | AK18: 463550.68 | AL18: 263918.94 | AM18: 70091.254 | AN18: 83089.071 | AO18: 22199.1 | AP18: 144466.34 | AQ18: 489132.68 | AR18: 282517.94 | AS18: 67751.254 | AT18: 122504.07 | AU18: 30444.1
A19: 45657 | B19: 96.74349 | C19: 103.7618 | D19: 139.96911 | E19: 118.48263 | F19: 27.90238 | G19: 32.04759 | H19: 13.686068 | I19: 13.905538 | J19: 14.507884 | K19: 10.667283 | L19: 209.23452 | M19: 7.3701937 | N19: 6.2414466 | O19: 6.7373314 | P19: 6.1360797 | Q19: 5.2922509 | R19: 4.2415833 | S19: 4.0316821 | T19: 1.9527085 | U19: 1.775994 | V19: 1.6821632 | W19: 2.3270967 | X19: 1.3455482 | Y19: 1.4698696 | Z19: 2.2216161 | AA19: 1.3396985 | AB19: 1.2634805 | AC19: 2.8822101 | AD19: 0.40959133 | AE19: 1.3367146 | AF19: 71.72 | AG19: 4.0265 | AH19: 654.84632 | AI19: 11169.347 | AJ19: 126527.7 | AK19: 468338.51 | AL19: 256223.74 | AM19: 68302.615 | AN19: 79718.351 | AO19: 21307.23 | AP19: 145244.7 | AQ19: 493920.51 | AR19: 274822.74 | AS19: 65962.615 | AT19: 119133.35 | AU19: 29552.23
A20: 45625 | B20: 105.68912 | C20: 113.78398 | D20: 156.48438 | E20: 128.80564 | F20: 27.6664 | G20: 36.91924 | H20: 12.536684 | I20: 15.384135 | J20: 17.445177 | K20: 10.497499 | L20: 28.864675 | M20: 7.3235473 | N20: 5.6101009 | O20: 7.2957515 | P20: 6.6717757 | Q20: 5.447231 | R20: 2.671304 | S20: 4.4635634 | T20: 2.4997466 | U20: 1.9302338 | V20: 1.8629915 | W20: 2.5343931 | X20: 1.2071103 | Y20: 1.74612 | Z20: 2.1676522 | AA20: 1.4791467 | AB20: 1.4715999 | AC20: 3.0630217 | AD20: 0.39297602 | AE20: 1.5896796 | AF20: 68 | AG20: 4.0805 | AH20: 724.05596 | AI20: 11446.164 | AJ20: 124689.86 | AK20: 518445.35 | AL20: 291003 | AM20: 74952.142 | AN20: 78252.135 | AO20: 24929.355 | AP20: 137772.86 | AQ20: 541877.35 | AR20: 312973 | AS20: 72606.142 | AT20: 116247.14 | AU20: 33338.355
... A68: 44165 | B68: 33.34864 | C68: 31.16404 | D68: 71.27706 | E68: 36.83312 | F68: 15.27118 | G68: 10.78976 | H68: -34.94659 | I68: 48.561014 | J68: -14.170722 | K68: -89.516398 | L68: -3.0526893 | M68: -1.6619158 | N68: 3.5319219 | O68: 5.7266464 | P68: 5.4958065 | Q68: 4.0111708 | R68: 4.1577136 | S68: 4.9245231 | T68: 1.3725247 | U68: 0.90880816 | V68: 1.2353974 | W68: 1.3573724 | X68: 0.97229647 | Y68: 1.7702179 | Z68: 1.9792209 | AA68: 0.79759847 | AB68: 1.5387468 | AC68: 2.207898 | AD68: 0.31903317 | AE68: 1.1214101 | AF68: 45.34 | AG68: 3.4205 | AH68: 274.4181 | AI68: 6585.1613 | AJ68: 42250.428 | AK68: 161222.57 | AL68: 162793.26 | AM68: 27348.782 | AN68: 66072.407 | AO68: 5351.3688 | AP68: 55147.428 | AQ68: 228401.57 | AR68: 191001.26 | AS68: 30003.959 | AT68: 122332.41 | AU68: 8066.3688
H69: 12.763687 | I69: 16.795169 | J69: 24.856773 | K69: 10.832345 | L69: 62.896785 | M69: 8.2686399 | N69: 5.6348922 | O69: 7.3671712 | P69: 7.9697078 | Q69: 5.1401532 | R69: 4.9901136 | S69: 4.037576 | T69: 1.7390998 | U69: 1.9307022 | V69: 1.6717565 | W69: 1.9779716 | X69: 1.6392645 | Y69: 1.4646536 | Z69: 1.8181574 | AA69: 1.5090944 | AB69: 1.6327027 | AC69: 2.6530347 | AD69: 0.49497042 | AE69: 1.2869165 | AJ69: 112907.58 | AK69: 503065.69 | AL69: 317371.27 | AM69: 59902.87 | AN69: 95477.32 | AO69: 22482.432 | AP69: 131129.58 | AQ69: 540094.69 | AR69: 356947.27 | AS69: 64066.87 | AT69: 140157.32 | AU69: 29595.432
H70: 12.763687 | I70: 16.795169 | J70: 24.856773 | K70: 10.832345 | L70: 62.896785 | M70: 8.2686399 | N70: 5.6348922 | O70: 7.3671712 | P70: 7.9697078 | Q70: 5.1401532 | R70: 4.9901136 | S70: 4.037576 | T70: 1.7390998 | U70: 1.9307022 | V70: 1.6717565 | W70: 1.9779716 | X70: 1.6392645 | Y70: 1.4646536 | Z70: 1.8181574 | AA70: 1.5090944 | AB70: 1.6327027 | AC70: 2.6530347 | AD70: 0.49497042 | AE70: 1.2869165 | AJ70: 112907.58 | AK70: 503065.69 | AL70: 317371.27 | AM70: 59902.87 | AN70: 95477.32 | AO70: 22482.432 | AP70: 131129.58 | AQ70: 540094.69 | AR70: 356947.27 | AS70: 64066.87 | AT70: 140157.32 | AU70: 29595.432
H71: 12.763687 | I71: 16.795169 | J71: 24.856773 | K71: 10.832345 | L71: 62.896785 | M71: 8.2686399 | N71: 5.6348922 | O71: 7.3671712 | P71: 7.9697078 | Q71: 5.1401532 | R71: 4.9901136 | S71: 4.037576 | T71: 1.7390998 | U71: 1.9307022 | V71: 1.6717565 | W71: 1.9779716 | X71: 1.6392645 | Y71: 1.4646536 | Z71: 1.8181574 | AA71: 1.5090944 | AB71: 1.6327027 | AC71: 2.6530347 | AD71: 0.49497042 | AE71: 1.2869165 | AJ71: 112907.58 | AK71: 503065.69 | AL71: 317371.27 | AM71: 59902.87 | AN71: 95477.32 | AO71: 22482.432 | AP71: 131129.58 | AQ71: 540094.69 | AR71: 356947.27 | AS71: 64066.87 | AT71: 140157.32 | AU71: 29595.432
H72: 12.763687 | I72: 16.795169 | J72: 24.856773 | K72: 10.832345 | L72: 62.896785 | M72: 8.2686399 | N72: 5.6348922 | O72: 7.3671712 | P72: 7.9697078 | Q72: 5.1401532 | R72: 4.9901136 | S72: 4.037576 | T72: 1.7390998 | U72: 1.9307022 | V72: 1.6717565 | W72: 1.9779716 | X72: 1.6392645 | Y72: 1.4646536 | Z72: 1.8181574 | AA72: 1.5090944 | AB72: 1.6327027 | AC72: 2.6530347 | AD72: 0.49497042 | AE72: 1.2869165 | AJ72: 112907.58 | AK72: 503065.69 | AL72: 317371.27 | AM72: 59902.87 | AN72: 95477.32 | AO72: 22482.432 | AP72: 131129.58 | AQ72: 540094.69 | AR72: 356947.27 | AS72: 64066.87 | AT72: 140157.32 | AU72: 29595.432
H73: 12.763687 | I73: 16.795169 | J73: 24.856773 | K73: 10.832345 | L73: 62.896785 | M73: 8.2686399 | N73: 5.6348922 | O73: 7.3671712 | P73: 7.9697078 | Q73: 5.1401532 | R73: 4.9901136 | S73: 4.037576 | T73: 1.7390998 | U73: 1.9307022 | V73: 1.6717565 | W73: 1.9779716 | X73: 1.6392645 | Y73: 1.4646536 | Z73: 1.8181574 | AA73: 1.5090944 | AB73: 1.6327027 | AC73: 2.6530347 | AD73: 0.49497042 | AE73: 1.2869165 | AJ73: 112907.58 | AK73: 503065.69 | AL73: 317371.27 | AM73: 59902.87 | AN73: 95477.32 | AO73: 22482.432 | AP73: 131129.58 | AQ73: 540094.69 | AR73: 356947.27 | AS73: 64066.87 | AT73: 140157.32 | AU73: 29595.432
H74: 12.763687 | I74: 16.795169 | J74: 24.856773 | K74: 10.832345 | L74: 62.896785 | M74: 8.2686399 | N74: 5.6348922 | O74: 7.3671712 | P74: 7.9697078 | Q74: 5.1401532 | R74: 4.9901136 | S74: 4.037576 | T74: 1.7390998 | U74: 1.9307022 | V74: 1.6717565 | W74: 1.9779716 | X74: 1.6392645 | Y74: 1.4646536 | Z74: 1.8181574 | AA74: 1.5090944 | AB74: 1.6327027 | AC74: 2.6530347 | AD74: 0.49497042 | AE74: 1.2869165 | AJ74: 112907.58 | AK74: 503065.69 | AL74: 317371.27 | AM74: 59902.87 | AN74: 95477.32 | AO74: 22482.432 | AP74: 131129.58 | AQ74: 540094.69 | AR74: 356947.27 | AS74: 64066.87 | AT74: 140157.32 | AU74: 29595.432
H75: 12.763687 | I75: 16.795169 | J75: 24.856773 | K75: 10.832345 | L75: 62.896785 | M75: 8.2686399 | N75: 5.6348922 | O75: 7.3671712 | P75: 7.9697078 | Q75: 5.1401532 | R75: 4.9901136 | S75: 4.037576 | T75: 1.7390998 | U75: 1.9307022 | V75: 1.6717565 | W75: 1.9779716 | X75: 1.6392645 | Y75: 1.4646536 | Z75: 1.8181574 | AA75: 1.5090944 | AB75: 1.6327027 | AC75: 2.6530347 | AD75: 0.49497042 | AE75: 1.2869165 | AJ75: 112907.58 | AK75: 503065.69 | AL75: 317371.27 | AM75: 59902.87 | AN75: 95477.32 | AO75: 22482.432 | AP75: 131129.58 | AQ75: 540094.69 | AR75: 356947.27 | AS75: 64066.87 | AT75: 140157.32 | AU75: 29595.432
H76: 12.763687 | I76: 16.795169 | J76: 24.856773 | K76: 10.832345 | L76: 62.896785 | M76: 8.2686399 | N76: 5.6348922 | O76: 7.3671712 | P76: 7.9697078 | Q76: 5.1401532 | R76: 4.9901136 | S76: 4.037576 | T76: 1.7390998 | U76: 1.9307022 | V76: 1.6717565 | W76: 1.9779716 | X76: 1.6392645 | Y76: 1.4646536 | Z76: 1.8181574 | AA76: 1.5090944 | AB76: 1.6327027 | AC76: 2.6530347 | AD76: 0.49497042 | AE76: 1.2869165 | AJ76: 112907.58 | AK76: 503065.69 | AL76: 317371.27 | AM76: 59902.87 | AN76: 95477.32 | AO76: 22482.432 | AP76: 131129.58 | AQ76: 540094.69 | AR76: 356947.27 | AS76: 64066.87 | AT76: 140157.32 | AU76: 29595.432
H77: 12.763687 | I77: 16.795169 | J77: 24.856773 | K77: 10.832345 | L77: 62.896785 | M77: 8.2686399 | N77: 5.6348922 | O77: 7.3671712 | P77: 7.9697078 | Q77: 5.1401532 | R77: 4.9901136 | S77: 4.037576 | T77: 1.7390998 | U77: 1.9307022 | V77: 1.6717565 | W77: 1.9779716 | X77: 1.6392645 | Y77: 1.4646536 | Z77: 1.8181574 | AA77: 1.5090944 | AB77: 1.6327027 | AC77: 2.6530347 | AD77: 0.49497042 | AE77: 1.2869165 | AJ77: 112907.58 | AK77: 503065.69 | AL77: 317371.27 | AM77: 59902.87 | AN77: 95477.32 | AO77: 22482.432 | AP77: 131129.58 | AQ77: 540094.69 | AR77: 356947.27 | AS77: 64066.87 | AT77: 140157.32 | AU77: 29595.432
H78: 12.763687 | I78: 16.795169 | J78: 24.856773 | K78: 10.832345 | L78: 62.896785 | M78: 8.2686399 | N78: 5.6348922 | O78: 7.3671712 | P78: 7.9697078 | Q78: 5.1401532 | R78: 4.9901136 | S78: 4.037576 | T78: 1.7390998 | U78: 1.9307022 | V78: 1.6717565 | W78: 1.9779716 | X78: 1.6392645 | Y78: 1.4646536 | Z78: 1.8181574 | AA78: 1.5090944 | AB78: 1.6327027 | AC78: 2.6530347 | AD78: 0.49497042 | AE78: 1.2869165 | AJ78: 112907.58 | AK78: 503065.69 | AL78: 317371.27 | AM78: 59902.87 | AN78: 95477.32 | AO78: 22482.432 | AP78: 131129.58 | AQ78: 540094.69 | AR78: 356947.27 | AS78: 64066.87 | AT78: 140157.32 | AU78: 29595.432
H79: 12.763687 | I79: 16.795169 | J79: 24.856773 | K79: 10.832345 | L79: 62.896785 | M79: 8.2686399 | N79: 5.6348922 | O79: 7.3671712 | P79: 7.9697078 | Q79: 5.1401532 | R79: 4.9901136 | S79: 4.037576 | T79: 1.7390998 | U79: 1.9307022 | V79: 1.6717565 | W79: 1.9779716 | X79: 1.6392645 | Y79: 1.4646536 | Z79: 1.8181574 | AA79: 1.5090944 | AB79: 1.6327027 | AC79: 2.6530347 | AD79: 0.49497042 | AE79: 1.2869165 | AJ79: 112907.58 | AK79: 503065.69 | AL79: 317371.27 | AM79: 59902.87 | AN79: 95477.32 | AO79: 22482.432 | AP79: 131129.58 | AQ79: 540094.69 | AR79: 356947.27 | AS79: 64066.87 | AT79: 140157.32 | AU79: 29595.432
H80: 12.763687 | I80: 16.795169 | J80: 24.856773 | K80: 10.832345 | L80: 62.896785 | M80: 8.2686399 | N80: 5.6348922 | O80: 7.3671712 | P80: 7.9697078 | Q80: 5.1401532 | R80: 4.9901136 | S80: 4.037576 | T80: 1.7390998 | U80: 1.9307022 | V80: 1.6717565 | W80: 1.9779716 | X80: 1.6392645 | Y80: 1.4646536 | Z80: 1.8181574 | AA80: 1.5090944 | AB80: 1.6327027 | AC80: 2.6530347 | AD80: 0.49497042 | AE80: 1.2869165 | AJ80: 112907.58 | AK80: 503065.69 | AL80: 317371.27 | AM80: 59902.87 | AN80: 95477.32 | AO80: 22482.432 | AP80: 131129.58 | AQ80: 540094.69 | AR80: 356947.27 | AS80: 64066.87 | AT80: 140157.32 | AU80: 29595.432
... H188: 12.763687 | I188: 16.795169 | J188: 24.856773 | K188: 10.832345 | L188: 62.896785 | M188: 8.2686399 | N188: 5.6348922 | O188: 7.3671712 | P188: 7.9697078 | Q188: 5.1401532 | R188: 4.9901136 | S188: 4.037576 | T188: 1.7390998 | U188: 1.9307022 | V188: 1.6717565 | W188: 1.9779716 | X188: 1.6392645 | Y188: 1.4646536 | Z188: 1.8181574 | AA188: 1.5090944 | AB188: 1.6327027 | AC188: 2.6530347 | AD188: 0.49497042 | AE188: 1.2869165 | AJ188: 112907.58 | AK188: 503065.69 | AL188: 317371.27 | AM188: 59902.87 | AN188: 95477.32 | AO188: 22482.432 | AP188: 131129.58 | AQ188: 540094.69 | AR188: 356947.27 | AS188: 64066.87 | AT188: 140157.32 | AU188: 29595.432

Sheet Financials
B1: ="IQ_Total_Revenue" -> IQ_Total_Revenue | N1: ="IQ_TOTAL_REV_1YR_ANN_GROWTH" -> IQ_TOTAL_REV_1YR_ANN_GROWTH | Z1: ="IQ_NI" -> IQ_NI | AL1: ="IQ_NI_1YR_ANN_Growth" -> IQ_NI_1YR_ANN_Growth | AX1: ="IQ_EBITDA" -> IQ_EBITDA | BI1: 4 | BJ1: IQ_EBITDA growth | BV1: ="IQ_RETURN_INVESTED_CAPITAL" -> IQ_RETURN_INVESTED_CAPITAL
B2: ="IQ_CQ" -> IQ_CQ | H2: ="IQ_LTM" -> IQ_LTM | N2: ="IQ_CQ" -> IQ_CQ | T2: =H2 -> IQ_LTM | Z2: =N2 -> IQ_CQ | AF2: =T2 -> IQ_LTM | AL2: =Z2 -> IQ_CQ | AR2: =AF2 -> IQ_LTM | AX2: =AL2 -> IQ_CQ | BD2: =AR2 -> IQ_LTM | BI2: =_xlfn.XMATCH("*",D:D,-1,2) -> 67 | BJ2: =AX2 -> IQ_CQ | BP2: =BD2 -> IQ_LTM | BV2: IQ_CQ | CB2: IQ_LTM
B3: {=Data!B6:G6} -> COP | C3: XOM | D3: CVX | E3: EOG | F3: BP | G3: DVN | H3: {=B3:G3} -> COP | I3: XOM | J3: CVX | K3: EOG | L3: BP | M3: DVN | N3: {=H3:M3} -> COP | O3: XOM | P3: CVX | Q3: EOG | R3: BP | S3: DVN | T3: {=_xlfn.ANCHORARRAY(N3)} -> COP | U3: XOM | V3: CVX | W3: EOG | X3: BP | Y3: DVN | Z3: {=_xlfn.ANCHORARRAY(T3)} -> COP | AA3: XOM | AB3: CVX | AC3: EOG | AD3: BP | AE3: DVN | AF3: {=_xlfn.ANCHORARRAY(Z3)} -> COP | AG3: XOM | AH3: CVX | AI3: EOG | AJ3: BP | AK3: DVN | AL3: {=_xlfn.ANCHORARRAY(AF3)} -> COP | AM3: XOM | AN3: CVX | AO3: EOG | AP3: BP | AQ3: DVN | AR3: {=_xlfn.ANCHORARRAY(AF3)} -> COP | AS3: XOM | AT3: CVX | AU3: EOG | AV3: BP | AW3: DVN | AX3: {=_xlfn.ANCHORARRAY(AL3)} -> COP | AY3: XOM | AZ3: CVX | BA3: EOG | BB3: BP | BC3: DVN | BD3: {=_xlfn.ANCHORARRAY(AX3)} -> COP | BE3: XOM | BF3: CVX | BG3: EOG | BH3: BP | BI3: DVN | BJ3: {=_xlfn.ANCHORARRAY(BD3)} -> COP | BK3: XOM | BL3: CVX | BM3: EOG | BN3: BP | BO3: DVN | BP3: {=_xlfn.ANCHORARRAY(BJ3)} -> COP | BQ3: XOM | BR3: CVX | BS3: EOG | BT3: BP | BU3: DVN | BV3: {=_xlfn.ANCHORARRAY(BP3)} -> COP | BW3: XOM | BX3: CVX | BY3: EOG | BZ3: BP | CA3: DVN | CB3: {=_xlfn.ANCHORARRAY(BV3)} -> COP | CC3: XOM | CD3: CVX | CE3: EOG | CF3: BP | CG3: DVN
A4: 45930 | B4: {=_xll.ciqfunctions.udf.CIQ(B$3,$B$1,$B$2,$A4,"L",,"USD","H")} -> 15376 | C4: {=_xll.ciqfunctions.udf.CIQ(C$3,$B$1,$B$2,$A4,"L",,"USD","H")} -> 83331 | D4: {=_xll.ciqfunctions.udf.CIQ(D$3,$B$1,$B$2,$A4,"L",,"USD","H")} -> 48747 | E4: {=_xll.ciqfunctions.udf.CIQ(E$3,$B$1,$B$2,$A4,"L",,"USD","H")} -> 5749 | F4: {=_xll.ciqfunctions.udf.CIQ(F$3,$B$1,$B$2,$A4,"L",,"USD","H")} -> 48386 | G4: {=_xll.ciqfunctions.udf.CIQ(G$3,$B$1,$B$2,$A4,"L",,"USD","H")} -> 4067 | H4: {=_xll.ciqfunctions.udf.CIQ(B$3,$B$1,$H$2,$A4,"L",,"USD","H")} -> 61280 | I4: {=_xll.ciqfunctions.udf.CIQ(C$3,$B$1,$H$2,$A4,"L",,"USD","H")} -> 326245 | J4: {=_xll.ciqfunctions.udf.CIQ(D$3,$B$1,$H$2,$A4,"L",,"USD","H")} -> 188687 | K4: {=_xll.ciqfunctions.udf.CIQ(E$3,$B$1,$H$2,$A4,"L",,"USD","H")} -> 22654 | L4: {=_xll.ciqfunctions.udf.CIQ(F$3,$B$1,$H$2,$A4,"L",,"USD","H")} -> 185934 | M4: {=_xll.ciqfunctions.udf.CIQ(G$3,$B$1,$H$2,$A4,"L",,"USD","H")} -> 16554 | N4: {=_xll.ciqfunctions.udf.CIQ(B$3,$N$1,$B$2,$A4,"L",,"USD","H")} -> 14.0483 | O4: {=_xll.ciqfunctions.udf.CIQ(C$3,$N$1,$B$2,$A4,"L",,"USD","H")} -> -5.0814 | P4: {=_xll.ciqfunctions.udf.CIQ(D$3,$N$1,$B$2,$A4,"L",,"USD","H")} -> -1.3539 | Q4: {=_xll.ciqfunctions.udf.CIQ(E$3,$N$1,$B$2,$A4,"L",,"USD","H")} -> -2.4436 | R4: {=_xll.ciqfunctions.udf.CIQ(F$3,$N$1,$B$2,$A4,"L",,"USD","H")} -> 2.4627 | S4: {=_xll.ciqfunctions.udf.CIQ(G$3,$N$1,$B$2,$A4,"L",,"USD","H")} -> 7.1108 | T4: {=_xll.ciqfunctions.udf.CIQ(N$3,$N$1,$T$2,$A4,"L",,"USD","H")} -> 7.6523 | U4: {=_xll.ciqfunctions.udf.CIQ(O$3,$N$1,$T$2,$A4,"L",,"USD","H")} -> -4.5635 | V4: {=_xll.ciqfunctions.udf.CIQ(P$3,$N$1,$T$2,$A4,"L",,"USD","H")} -> -1.5661 | W4: {=_xll.ciqfunctions.udf.CIQ(Q$3,$N$1,$T$2,$A4,"L",,"USD","H")} -> -5.0704 | X4: {=_xll.ciqfunctions.udf.CIQ(R$3,$N$1,$T$2,$A4,"L",,"USD","H")} -> -4.1227 | Y4: {=_xll.ciqfunctions.udf.CIQ(S$3,$N$1,$T$2,$A4,"L",,"USD","H")} -> 13.9376 | Z4: {=_xll.ciqfunctions.udf.CIQ(B$3,$Z$1,$B$2,$A4,"L",,"USD","H")} -> 1726 | AA4: {=_xll.ciqfunctions.udf.CIQ(C$3,$Z$1,$B$2,$A4,"L",,"USD","H")} -> 7548 | AB4: {=_xll.ciqfunctions.udf.CIQ(D$3,$Z$1,$B$2,$A4,"L",,"USD","H")} -> 3539 | AC4: {=_xll.ciqfunctions.udf.CIQ(E$3,$Z$1,$B$2,$A4,"L",,"USD","H")} -> 1471 | AD4: {=_xll.ciqfunctions.udf.CIQ(F$3,$Z$1,$B$2,$A4,"L",,"USD","H")} -> 1161 | AE4: {=_xll.ciqfunctions.udf.CIQ(G$3,$Z$1,$B$2,$A4,"L",,"USD","H")} -> 687 | AF4: {=_xll.ciqfunctions.udf.CIQ(B$3,$Z$1,$H$2,$A4,"L",,"USD","H")} -> 8852 | AG4: {=_xll.ciqfunctions.udf.CIQ(C$3,$Z$1,$H$2,$A4,"L",,"USD","H")} -> 29953 | AH4: {=_xll.ciqfunctions.udf.CIQ(D$3,$Z$1,$H$2,$A4,"L",,"USD","H")} -> 12768 | AI4: {=_xll.ciqfunctions.udf.CIQ(E$3,$Z$1,$H$2,$A4,"L",,"USD","H")} -> 5530 | AJ4: {=_xll.ciqfunctions.udf.CIQ(F$3,$Z$1,$H$2,$A4,"L",,"USD","H")} -> 1518 | AK4: {=_xll.ciqfunctions.udf.CIQ(G$3,$Z$1,$H$2,$A4,"L",,"USD","H")} -> 2719 | AL4: {=_xll.ciqfunctions.udf.CIQ(B$3,$AL$1,$AL$2,$A4,"L",,"USD","H")} -> -16.1729 | AM4: {=_xll.ciqfunctions.udf.CIQ(C$3,$AL$1,$AL$2,$A4,"L",,"USD","H")} -> -12.3345 | AN4: {=_xll.ciqfunctions.udf.CIQ(D$3,$AL$1,$AL$2,$A4,"L",,"USD","H")} -> -21.1278 | AO4: {=_xll.ciqfunctions.udf.CIQ(E$3,$AL$1,$AL$2,$A4,"L",,"USD","H")} -> -12.0742 | AP4: {=_xll.ciqfunctions.udf.CIQ(F$3,$AL$1,$AL$2,$A4,"L",,"USD","H")} -> 463.5922 | AQ4: {=_xll.ciqfunctions.udf.CIQ(G$3,$AL$1,$AL$2,$A4,"L",,"USD","H")} -> -15.3941 | AR4: {=_xll.ciqfunctions.udf.CIQ(B$3,$AL$1,$AR$2,$A4,"L",,"USD","H")} -> -10.9994 | AS4: {=_xll.ciqfunctions.udf.CIQ(C$3,$AL$1,$AR$2,$A4,"L",,"USD","H")} -> -11.1187 | AT4: {=_xll.ciqfunctions.udf.CIQ(D$3,$AL$1,$AR$2,$A4,"L",,"USD","H")} -> -23.4579 | AU4: {=_xll.ciqfunctions.udf.CIQ(E$3,$AL$1,$AR$2,$A4,"L",,"USD","H")} -> -22.5491 | AV4: {=_xll.ciqfunctions.udf.CIQ(F$3,$AL$1,$AR$2,$A4,"L",,"USD","H")} -> -44.006 | AW4: {=_xll.ciqfunctions.udf.CIQ(G$3,$AL$1,$AR$2,$A4,"L",,"USD","H")} -> -20.1234 | AX4: {=_xll.ciqfunctions.udf.CIQ(B$3,$AX$1,$AX$2,$A4,"L",,"USD","H")} -> 5942 | AY4: {=_xll.ciqfunctions.udf.CIQ(C$3,$AX$1,$AX$2,$A4,"L",,"USD","H")} -> 15689 | AZ4: {=_xll.ciqfunctions.udf.CIQ(D$3,$AX$1,$AX$2,$A4,"L",,"USD","H")} -> 10584 | BA4: {=_xll.ciqfunctions.udf.CIQ(E$3,$AX$1,$AX$2,$A4,"L",,"USD","H")} -> 3094 | BB4: {=_xll.ciqfunctions.udf.CIQ(F$3,$AX$1,$AX$2,$A4,"L",,"USD","H")} -> 9478 | BC4: {=_xll.ciqfunctions.udf.CIQ(G$3,$AX$1,$AX$2,$A4,"L",,"USD","H")} -> 1863 | BD4: {=_xll.ciqfunctions.udf.CIQ(B$3,$AX$1,$BD$2,$A4,"L",,"USD","H")} -> 25422 | BE4: {=_xll.ciqfunctions.udf.CIQ(C$3,$AX$1,$BD$2,$A4,"L",,"USD","H")} -> 61694 | BF4: {=_xll.ciqfunctions.udf.CIQ(D$3,$AX$1,$BD$2,$A4,"L",,"USD","H")} -> 37683 | BG4: {=_xll.ciqfunctions.udf.CIQ(E$3,$AX$1,$BD$2,$A4,"L",,"USD","H")} -> 11760 | BH4: {=_xll.ciqfunctions.udf.CIQ(F$3,$AX$1,$BD$2,$A4,"L",,"USD","H")} -> 28658 | BI4: {=_xll.ciqfunctions.udf.CIQ(G$3,$AX$1,$BD$2,$A4,"L",,"USD","H")} -> 7670 | BJ4: =AX4/AX8-1 -> 0.049267173 | BK4: =AY4/AY8-1 -> -0.091388197 | BL4: =AZ4/AZ8-1 -> 0.10181137 | BM4: =BA4/BA8-1 -> -0.015276894 | BN4: =BB4/BB8-1 -> 0.16580566 | BO4: =BC4/BC8-1 -> -0.042651593 | BP4: =BD4/BD8-1 -> 0.039924732 | BQ4: =BE4/BE8-1 -> -0.073594114 | ... BU4: =BI4/BI8-1 -> 0.0076195481 | BV4: {=_xll.ciqfunctions.udf.CIQ(B$3,$BV$1,$BV$2,$A4,"L",,"USD","H")/100} -> 0.033844 | BW4: {=_xll.ciqfunctions.udf.CIQ(C$3,$BV$1,$BV$2,$A4,"L",,"USD","H")/100} -> 0.042712 | BX4: {=_xll.ciqfunctions.udf.CIQ(D$3,$BV$1,$BV$2,$A4,"L",,"USD","H")/100} -> 0.002124 | BY4: {=_xll.ciqfunctions.udf.CIQ(E$3,$BV$1,$BV$2,$A4,"L",,"USD","H")/100} -> 0.102536 | BZ4: {=_xll.ciqfunctions.udf.CIQ(F$3,$BV$1,$BV$2,$A4,"L",,"USD","H")/100} -> -0.003304 | CA4: {=_xll.ciqfunctions.udf.CIQ(G$3,$BV$1,$BV$2,$A4,"L",,"USD","H")/100} -> 0.088696 | CB4: {=_xll.ciqfunctions.udf.CIQ(B$3,$BV$1,$CB$2,$A4,"L",,"USD","H")/100} -> 0.063835 | CC4: {=_xll.ciqfunctions.udf.CIQ(C$3,$BV$1,$CB$2,$A4,"L",,"USD","H")/100} -> 0.040422 | CD4: {=_xll.ciqfunctions.udf.CIQ(D$3,$BV$1,$CB$2,$A4,"L",,"USD","H")/100} -> 0.002542 | CE4: {=_xll.ciqfunctions.udf.CIQ(E$3,$BV$1,$CB$2,$A4,"L",,"USD","H")/100} -> 0.09459 | CF4: {=_xll.ciqfunctions.udf.CIQ(F$3,$BV$1,$CB$2,$A4,"L",,"USD","H")/100} -> -0.023582 | CG4: {=_xll.ciqfunctions.udf.CIQ(G$3,$BV$1,$CB$2,$A4,"L",,"USD","H")/100} -> 0.088237
A5: 45838 | B5: {=_xll.ciqfunctions.udf.CIQ(B$3,$B$1,$B$2,$A5,"L",,"USD","H")} -> 14319 | C5: {=_xll.ciqfunctions.udf.CIQ(C$3,$B$1,$B$2,$A5,"L",,"USD","H")} -> 79477 | D5: {=_xll.ciqfunctions.udf.CIQ(D$3,$B$1,$B$2,$A5,"L",,"USD","H")} -> 44516 | E5: {=_xll.ciqfunctions.udf.CIQ(E$3,$B$1,$B$2,$A5,"L",,"USD","H")} -> 5371 | F5: {=_xll.ciqfunctions.udf.CIQ(F$3,$B$1,$B$2,$A5,"L",,"USD","H")} -> 46973 | G5: {=_xll.ciqfunctions.udf.CIQ(G$3,$B$1,$B$2,$A5,"L",,"USD","H")} -> 3868 | H5: {=_xll.ciqfunctions.udf.CIQ(B$3,$B$1,$H$2,$A5,"L",,"USD","H")} -> 59386 | I5: {=_xll.ciqfunctions.udf.CIQ(C$3,$B$1,$H$2,$A5,"L",,"USD","H")} -> 330706 | J5: {=_xll.ciqfunctions.udf.CIQ(D$3,$B$1,$H$2,$A5,"L",,"USD","H")} -> 189356 | K5: {=_xll.ciqfunctions.udf.CIQ(E$3,$B$1,$H$2,$A5,"L",,"USD","H")} -> 22798 | L5: {=_xll.ciqfunctions.udf.CIQ(F$3,$B$1,$H$2,$A5,"L",,"USD","H")} -> 184771 | M5: {=_xll.ciqfunctions.udf.CIQ(G$3,$B$1,$H$2,$A5,"L",,"USD","H")} -> 16105 | N5: {=_xll.ciqfunctions.udf.CIQ(B$3,$N$1,$B$2,$A5,"L",,"USD","H")} -> 2.1108 | O5: {=_xll.ciqfunctions.udf.CIQ(C$3,$N$1,$B$2,$A5,"L",,"USD","H")} -> -11.6785 | P5: {=_xll.ciqfunctions.udf.CIQ(D$3,$N$1,$B$2,$A5,"L",,"USD","H")} -> -10.571 | Q5: {=_xll.ciqfunctions.udf.CIQ(E$3,$N$1,$B$2,$A5,"L",,"USD","H")} -> -11.2525 | R5: {=_xll.ciqfunctions.udf.CIQ(F$3,$N$1,$B$2,$A5,"L",,"USD","H")} -> -1.338 | S5: {=_xll.ciqfunctions.udf.CIQ(G$3,$N$1,$B$2,$A5,"L",,"USD","H")} -> -0.6677 | T5: {=_xll.ciqfunctions.udf.CIQ(N$3,$N$1,$T$2,$A5,"L",,"USD","H")} -> 2.2486 | U5: {=_xll.ciqfunctions.udf.CIQ(O$3,$N$1,$T$2,$A5,"L",,"USD","H")} -> -3.4782 | V5: {=_xll.ciqfunctions.udf.CIQ(P$3,$N$1,$T$2,$A5,"L",,"USD","H")} -> -2.9183 | W5: {=_xll.ciqfunctions.udf.CIQ(Q$3,$N$1,$T$2,$A5,"L",,"USD","H")} -> -5.4222 | X5: {=_xll.ciqfunctions.udf.CIQ(R$3,$N$1,$T$2,$A5,"L",,"USD","H")} -> -7.5817 | Y5: {=_xll.ciqfunctions.udf.CIQ(S$3,$N$1,$T$2,$A5,"L",,"USD","H")} -> 7.7906 | Z5: {=_xll.ciqfunctions.udf.CIQ(B$3,$Z$1,$B$2,$A5,"L",,"USD","H")} -> 1971 | AA5: {=_xll.ciqfunctions.udf.CIQ(C$3,$Z$1,$B$2,$A5,"L",,"USD","H")} -> 7082 | AB5: {=_xll.ciqfunctions.udf.CIQ(D$3,$Z$1,$B$2,$A5,"L",,"USD","H")} -> 2490 | AC5: {=_xll.ciqfunctions.udf.CIQ(E$3,$Z$1,$B$2,$A5,"L",,"USD","H")} -> 1345 | AD5: {=_xll.ciqfunctions.udf.CIQ(F$3,$Z$1,$B$2,$A5,"L",,"USD","H")} -> 1629 | AE5: {=_xll.ciqfunctions.udf.CIQ(G$3,$Z$1,$B$2,$A5,"L",,"USD","H")} -> 899 | AF5: {=_xll.ciqfunctions.udf.CIQ(B$3,$Z$1,$H$2,$A5,"L",,"USD","H")} -> 9185 | AG5: {=_xll.ciqfunctions.udf.CIQ(C$3,$Z$1,$H$2,$A5,"L",,"USD","H")} -> 31015 | AH5: {=_xll.ciqfunctions.udf.CIQ(D$3,$Z$1,$H$2,$A5,"L",,"USD","H")} -> 13716 | AI5: {=_xll.ciqfunctions.udf.CIQ(E$3,$Z$1,$H$2,$A5,"L",,"USD","H")} -> 5732 | AJ5: {=_xll.ciqfunctions.udf.CIQ(F$3,$Z$1,$H$2,$A5,"L",,"USD","H")} -> 563 | AK5: {=_xll.ciqfunctions.udf.CIQ(G$3,$Z$1,$H$2,$A5,"L",,"USD","H")} -> 2844 | AL5: {=_xll.ciqfunctions.udf.CIQ(B$3,$AL$1,$AL$2,$A5,"L",,"USD","H")} -> -15.3715 | AM5: {=_xll.ciqfunctions.udf.CIQ(C$3,$AL$1,$AL$2,$A5,"L",,"USD","H")} -> -23.355 | AN5: {=_xll.ciqfunctions.udf.CIQ(D$3,$AL$1,$AL$2,$A5,"L",,"USD","H")} -> -43.8431 | AO5: {=_xll.ciqfunctions.udf.CIQ(E$3,$AL$1,$AL$2,$A5,"L",,"USD","H")} -> -20.4143 | AP5: {=_xll.ciqfunctions.udf.CIQ(F$3,$AL$1,$AL$2,$A5,"L",,"USD","H")} -> NM | AQ5: {=_xll.ciqfunctions.udf.CIQ(G$3,$AL$1,$AL$2,$A5,"L",,"USD","H")} -> 6.5165 | AR5: {=_xll.ciqfunctions.udf.CIQ(B$3,$AL$1,$AR$2,$A5,"L",,"USD","H")} -> -14.0384 | AS5: {=_xll.ciqfunctions.udf.CIQ(C$3,$AL$1,$AR$2,$A5,"L",,"USD","H")} -> -9.2067 | AT5: {=_xll.ciqfunctions.udf.CIQ(D$3,$AL$1,$AR$2,$A5,"L",,"USD","H")} -> -26.7308 | AU5: {=_xll.ciqfunctions.udf.CIQ(E$3,$AL$1,$AR$2,$A5,"L",,"USD","H")} -> -23.5428 | AV5: {=_xll.ciqfunctions.udf.CIQ(F$3,$AL$1,$AR$2,$A5,"L",,"USD","H")} -> -92.3537 | AW5: {=_xll.ciqfunctions.udf.CIQ(G$3,$AL$1,$AR$2,$A5,"L",,"USD","H")} -> -18.7893 | AX5: {=_xll.ciqfunctions.udf.CIQ(B$3,$AX$1,$AX$2,$A5,"L",,"USD","H")} -> 5681 | AY5: {=_xll.ciqfunctions.udf.CIQ(C$3,$AX$1,$AX$2,$A5,"L",,"USD","H")} -> 14922 | AZ5: {=_xll.ciqfunctions.udf.CIQ(D$3,$AX$1,$AX$2,$A5,"L",,"USD","H")} -> 8458 | BA5: {=_xll.ciqfunctions.udf.CIQ(E$3,$AX$1,$AX$2,$A5,"L",,"USD","H")} -> 2839 | BB5: {=_xll.ciqfunctions.udf.CIQ(F$3,$AX$1,$AX$2,$A5,"L",,"USD","H")} -> 9702 | BC5: {=_xll.ciqfunctions.udf.CIQ(G$3,$AX$1,$AX$2,$A5,"L",,"USD","H")} -> 1884 | BD5: {=_xll.ciqfunctions.udf.CIQ(B$3,$AX$1,$BD$2,$A5,"L",,"USD","H")} -> 25143 | BE5: {=_xll.ciqfunctions.udf.CIQ(C$3,$AX$1,$BD$2,$A5,"L",,"USD","H")} -> 63272 | BF5: {=_xll.ciqfunctions.udf.CIQ(D$3,$AX$1,$BD$2,$A5,"L",,"USD","H")} -> 36705 | BG5: {=_xll.ciqfunctions.udf.CIQ(E$3,$AX$1,$BD$2,$A5,"L",,"USD","H")} -> 11808 | BH5: {=_xll.ciqfunctions.udf.CIQ(F$3,$AX$1,$BD$2,$A5,"L",,"USD","H")} -> 27310 | BI5: {=_xll.ciqfunctions.udf.CIQ(G$3,$AX$1,$BD$2,$A5,"L",,"USD","H")} -> 7744 | BJ5: =AX5/AX9-1 -> -0.072489796 | BK5: =AY5/AY9-1 -> -0.10372995 | BL5: =AZ5/AZ9-1 -> -0.13322402 | BM5: =BA5/BA9-1 -> -0.10582677 | BN5: =BB5/BB9-1 -> 0.23623853 | BO5: =BC5/BC9-1 -> -0.022314478 | BP5: =BD5/BD9-1 -> 0.0049562333 | BQ5: =BE5/BE9-1 -> -0.032848779 | ... BU5: =BI5/BI9-1 -> 0.036541293 | BV5: {=_xll.ciqfunctions.udf.CIQ(B$3,$BV$1,$BV$2,$A5,"L",,"USD","H")/100} -> 0.044328 | BW5: {=_xll.ciqfunctions.udf.CIQ(C$3,$BV$1,$BV$2,$A5,"L",,"USD","H")/100} -> 0.036264 | BX5: {=_xll.ciqfunctions.udf.CIQ(D$3,$BV$1,$BV$2,$A5,"L",,"USD","H")/100} -> -0.00996 | BY5: {=_xll.ciqfunctions.udf.CIQ(E$3,$BV$1,$BV$2,$A5,"L",,"USD","H")/100} -> 0.095536 | BZ5: {=_xll.ciqfunctions.udf.CIQ(F$3,$BV$1,$BV$2,$A5,"L",,"USD","H")/100} -> 0.042888 | CA5: {=_xll.ciqfunctions.udf.CIQ(G$3,$BV$1,$BV$2,$A5,"L",,"USD","H")/100} -> 0.123484 | CB5: {=_xll.ciqfunctions.udf.CIQ(B$3,$BV$1,$CB$2,$A5,"L",,"USD","H")/100} -> 0.068652 | CC5: {=_xll.ciqfunctions.udf.CIQ(C$3,$BV$1,$CB$2,$A5,"L",,"USD","H")/100} -> 0.04386 | CD5: {=_xll.ciqfunctions.udf.CIQ(D$3,$BV$1,$CB$2,$A5,"L",,"USD","H")/100} -> 0.010983 | CE5: {=_xll.ciqfunctions.udf.CIQ(E$3,$BV$1,$CB$2,$A5,"L",,"USD","H")/100} -> 0.10805 | CF5: {=_xll.ciqfunctions.udf.CIQ(F$3,$BV$1,$CB$2,$A5,"L",,"USD","H")/100} -> -0.029341 | CG5: {=_xll.ciqfunctions.udf.CIQ(G$3,$BV$1,$CB$2,$A5,"L",,"USD","H")/100} -> 0.09682
A6: 45747 | B6: {=_xll.ciqfunctions.udf.CIQ(B$3,$B$1,$B$2,$A6,"L",,"USD","H")} -> 16909 | C6: {=_xll.ciqfunctions.udf.CIQ(C$3,$B$1,$B$2,$A6,"L",,"USD","H")} -> 81058 | D6: {=_xll.ciqfunctions.udf.CIQ(D$3,$B$1,$B$2,$A6,"L",,"USD","H")} -> 46265 | E6: {=_xll.ciqfunctions.udf.CIQ(E$3,$B$1,$B$2,$A6,"L",,"USD","H")} -> 5861 | F6: {=_xll.ciqfunctions.udf.CIQ(F$3,$B$1,$B$2,$A6,"L",,"USD","H")} -> 46458 | G6: {=_xll.ciqfunctions.udf.CIQ(G$3,$B$1,$B$2,$A6,"L",,"USD","H")} -> 4338 | H6: {=_xll.ciqfunctions.udf.CIQ(B$3,$B$1,$H$2,$A6,"L",,"USD","H")} -> 59090 | I6: {=_xll.ciqfunctions.udf.CIQ(C$3,$B$1,$H$2,$A6,"L",,"USD","H")} -> 341215 | J6: {=_xll.ciqfunctions.udf.CIQ(D$3,$B$1,$H$2,$A6,"L",,"USD","H")} -> 194618 | K6: {=_xll.ciqfunctions.udf.CIQ(E$3,$B$1,$H$2,$A6,"L",,"USD","H")} -> 23479 | L6: {=_xll.ciqfunctions.udf.CIQ(F$3,$B$1,$H$2,$A6,"L",,"USD","H")} -> 185408 | M6: {=_xll.ciqfunctions.udf.CIQ(G$3,$B$1,$H$2,$A6,"L",,"USD","H")} -> 15943 | N6: {=_xll.ciqfunctions.udf.CIQ(B$3,$N$1,$B$2,$A6,"L",,"USD","H")} -> 18.5016 | O6: {=_xll.ciqfunctions.udf.CIQ(C$3,$N$1,$B$2,$A6,"L",,"USD","H")} -> 0.8046 | P6: {=_xll.ciqfunctions.udf.CIQ(D$3,$N$1,$B$2,$A6,"L",,"USD","H")} -> -2.0121 | Q6: {=_xll.ciqfunctions.udf.CIQ(E$3,$N$1,$B$2,$A6,"L",,"USD","H")} -> 0.017 | R6: {=_xll.ciqfunctions.udf.CIQ(F$3,$N$1,$B$2,$A6,"L",,"USD","H")} -> -4.0838 | S6: {=_xll.ciqfunctions.udf.CIQ(G$3,$N$1,$B$2,$A6,"L",,"USD","H")} -> 21.6489 | T6: {=_xll.ciqfunctions.udf.CIQ(N$3,$N$1,$T$2,$A6,"L",,"USD","H")} -> 3.995 | U6: {=_xll.ciqfunctions.udf.CIQ(O$3,$N$1,$T$2,$A6,"L",,"USD","H")} -> 2.4999 | V6: {=_xll.ciqfunctions.udf.CIQ(P$3,$N$1,$T$2,$A6,"L",,"USD","H")} -> 0.9413 | W6: {=_xll.ciqfunctions.udf.CIQ(Q$3,$N$1,$T$2,$A6,"L",,"USD","H")} -> -0.2338 | X6: {=_xll.ciqfunctions.udf.CIQ(R$3,$N$1,$T$2,$A6,"L",,"USD","H")} -> -7.7935 | Y6: {=_xll.ciqfunctions.udf.CIQ(S$3,$N$1,$T$2,$A6,"L",,"USD","H")} -> 9.3934 | Z6: {=_xll.ciqfunctions.udf.CIQ(B$3,$Z$1,$B$2,$A6,"L",,"USD","H")} -> 2849 | AA6: {=_xll.ciqfunctions.udf.CIQ(C$3,$Z$1,$B$2,$A6,"L",,"USD","H")} -> 7713 | AB6: {=_xll.ciqfunctions.udf.CIQ(D$3,$Z$1,$B$2,$A6,"L",,"USD","H")} -> 3500 | AC6: {=_xll.ciqfunctions.udf.CIQ(E$3,$Z$1,$B$2,$A6,"L",,"USD","H")} -> 1463 | AD6: {=_xll.ciqfunctions.udf.CIQ(F$3,$Z$1,$B$2,$A6,"L",,"USD","H")} -> 687 | AE6: {=_xll.ciqfunctions.udf.CIQ(G$3,$Z$1,$B$2,$A6,"L",,"USD","H")} -> 494 | AF6: {=_xll.ciqfunctions.udf.CIQ(B$3,$Z$1,$H$2,$A6,"L",,"USD","H")} -> 9543 | AG6: {=_xll.ciqfunctions.udf.CIQ(C$3,$Z$1,$H$2,$A6,"L",,"USD","H")} -> 33173 | AH6: {=_xll.ciqfunctions.udf.CIQ(D$3,$Z$1,$H$2,$A6,"L",,"USD","H")} -> 15660 | AI6: {=_xll.ciqfunctions.udf.CIQ(E$3,$Z$1,$H$2,$A6,"L",,"USD","H")} -> 6077 | AJ6: {=_xll.ciqfunctions.udf.CIQ(F$3,$Z$1,$H$2,$A6,"L",,"USD","H")} -> -1195 | AK6: {=_xll.ciqfunctions.udf.CIQ(G$3,$Z$1,$H$2,$A6,"L",,"USD","H")} -> 2789 | AL6: {=_xll.ciqfunctions.udf.CIQ(B$3,$AL$1,$AL$2,$A6,"L",,"USD","H")} -> 11.6816 | AM6: {=_xll.ciqfunctions.udf.CIQ(C$3,$AL$1,$AL$2,$A6,"L",,"USD","H")} -> -6.1679 | AN6: {=_xll.ciqfunctions.udf.CIQ(D$3,$AL$1,$AL$2,$A6,"L",,"USD","H")} -> -36.3753 | AO6: {=_xll.ciqfunctions.udf.CIQ(E$3,$AL$1,$AL$2,$A6,"L",,"USD","H")} -> -18.2225 | AP6: {=_xll.ciqfunctions.udf.CIQ(F$3,$AL$1,$AL$2,$A6,"L",,"USD","H")} -> -69.6421 | AQ6: {=_xll.ciqfunctions.udf.CIQ(G$3,$AL$1,$AL$2,$A6,"L",,"USD","H")} -> -17.1141 | AR6: {=_xll.ciqfunctions.udf.CIQ(B$3,$AL$1,$AR$2,$A6,"L",,"USD","H")} -> -9.8697 | AS6: {=_xll.ciqfunctions.udf.CIQ(C$3,$AL$1,$AR$2,$A6,"L",,"USD","H")} -> 1.1371 | AT6: {=_xll.ciqfunctions.udf.CIQ(D$3,$AL$1,$AR$2,$A6,"L",,"USD","H")} -> -22.842 | AU6: {=_xll.ciqfunctions.udf.CIQ(E$3,$AL$1,$AR$2,$A6,"L",,"USD","H")} -> -17.4321 | AV6: {=_xll.ciqfunctions.udf.CIQ(F$3,$AL$1,$AR$2,$A6,"L",,"USD","H")} -> NM | AW6: {=_xll.ciqfunctions.udf.CIQ(G$3,$AL$1,$AR$2,$A6,"L",,"USD","H")} -> -16.6966 | AX6: {=_xll.ciqfunctions.udf.CIQ(B$3,$AX$1,$AX$2,$A6,"L",,"USD","H")} -> 7275 | AY6: {=_xll.ciqfunctions.udf.CIQ(C$3,$AX$1,$AX$2,$A6,"L",,"USD","H")} -> 15435 | AZ6: {=_xll.ciqfunctions.udf.CIQ(D$3,$AX$1,$AX$2,$A6,"L",,"USD","H")} -> 8567 | BA6: {=_xll.ciqfunctions.udf.CIQ(E$3,$AX$1,$AX$2,$A6,"L",,"USD","H")} -> 2917 | BB6: {=_xll.ciqfunctions.udf.CIQ(F$3,$AX$1,$AX$2,$A6,"L",,"USD","H")} -> 8215 | BC6: {=_xll.ciqfunctions.udf.CIQ(G$3,$AX$1,$AX$2,$A6,"L",,"USD","H")} -> 1937 | BD6: {=_xll.ciqfunctions.udf.CIQ(B$3,$AX$1,$BD$2,$A6,"L",,"USD","H")} -> 25587 | BE6: {=_xll.ciqfunctions.udf.CIQ(C$3,$AX$1,$BD$2,$A6,"L",,"USD","H")} -> 64999 | BF6: {=_xll.ciqfunctions.udf.CIQ(D$3,$AX$1,$BD$2,$A6,"L",,"USD","H")} -> 38005 | BG6: {=_xll.ciqfunctions.udf.CIQ(E$3,$AX$1,$BD$2,$A6,"L",,"USD","H")} -> 12144 | BH6: {=_xll.ciqfunctions.udf.CIQ(F$3,$AX$1,$BD$2,$A6,"L",,"USD","H")} -> 25456 | BI6: {=_xll.ciqfunctions.udf.CIQ(G$3,$AX$1,$BD$2,$A6,"L",,"USD","H")} -> 7759 | BJ6: =AX6/AX10-1 -> 0.21330887 | BK6: =AY6/AY10-1 -> 0.047861507 | BL6: =AZ6/AZ10-1 -> -0.19505778 | BM6: =BA6/BA10-1 -> -0.12612343 | BN6: =BB6/BB10-1 -> -0.15483539 | BO6: =BC6/BC10-1 -> 0.23611997 | BP6: =BD6/BD10-1 -> 0.053526578 | BQ6: =BE6/BE10-1 -> 0.043976165 | ... BU6: =BI6/BI10-1 -> 0.086694678 | BV6: {=_xll.ciqfunctions.udf.CIQ(B$3,$BV$1,$BV$2,$A6,"L",,"USD","H")/100} -> 0.082648 | BW6: {=_xll.ciqfunctions.udf.CIQ(C$3,$BV$1,$BV$2,$A6,"L",,"USD","H")/100} -> 0.043148 | BX6: {=_xll.ciqfunctions.udf.CIQ(D$3,$BV$1,$BV$2,$A6,"L",,"USD","H")/100} -> 0.011384 | BY6: {=_xll.ciqfunctions.udf.CIQ(E$3,$BV$1,$BV$2,$A6,"L",,"USD","H")/100} -> 0.106136 | BZ6: {=_xll.ciqfunctions.udf.CIQ(F$3,$BV$1,$BV$2,$A6,"L",,"USD","H")/100} -> -0.015252 | CA6: {=_xll.ciqfunctions.udf.CIQ(G$3,$BV$1,$BV$2,$A6,"L",,"USD","H")/100} -> 0.055464 | CB6: {=_xll.ciqfunctions.udf.CIQ(B$3,$BV$1,$CB$2,$A6,"L",,"USD","H")/100} -> 0.07429 | CC6: {=_xll.ciqfunctions.udf.CIQ(C$3,$BV$1,$CB$2,$A6,"L",,"USD","H")/100} -> 0.056849 | CD6: {=_xll.ciqfunctions.udf.CIQ(D$3,$BV$1,$CB$2,$A6,"L",,"USD","H")/100} -> 0.021351 | CE6: {=_xll.ciqfunctions.udf.CIQ(E$3,$BV$1,$CB$2,$A6,"L",,"USD","H")/100} -> 0.118146 | CF6: {=_xll.ciqfunctions.udf.CIQ(F$3,$BV$1,$CB$2,$A6,"L",,"USD","H")/100} -> -0.041839 | CG6: {=_xll.ciqfunctions.udf.CIQ(G$3,$BV$1,$CB$2,$A6,"L",,"USD","H")/100} -> 0.093317
A7: 45657 | B7: {=_xll.ciqfunctions.udf.CIQ(B$3,$B$1,$B$2,$A7,"L",,"USD","H")} -> 14676 | C7: {=_xll.ciqfunctions.udf.CIQ(C$3,$B$1,$B$2,$A7,"L",,"USD","H")} -> 82379 | D7: {=_xll.ciqfunctions.udf.CIQ(D$3,$B$1,$B$2,$A7,"L",,"USD","H")} -> 49159 | E7: {=_xll.ciqfunctions.udf.CIQ(E$3,$B$1,$B$2,$A7,"L",,"USD","H")} -> 5673 | F7: {=_xll.ciqfunctions.udf.CIQ(F$3,$B$1,$B$2,$A7,"L",,"USD","H")} -> 44117 | G7: {=_xll.ciqfunctions.udf.CIQ(G$3,$B$1,$B$2,$A7,"L",,"USD","H")} -> 4281 | H7: {=_xll.ciqfunctions.udf.CIQ(B$3,$B$1,$H$2,$A7,"L",,"USD","H")} -> 56450 | I7: {=_xll.ciqfunctions.udf.CIQ(C$3,$B$1,$H$2,$A7,"L",,"USD","H")} -> 340568 | J7: {=_xll.ciqfunctions.udf.CIQ(D$3,$B$1,$H$2,$A7,"L",,"USD","H")} -> 195568 | K7: {=_xll.ciqfunctions.udf.CIQ(E$3,$B$1,$H$2,$A7,"L",,"USD","H")} -> 23478 | L7: {=_xll.ciqfunctions.udf.CIQ(F$3,$B$1,$H$2,$A7,"L",,"USD","H")} -> 187386 | M7: {=_xll.ciqfunctions.udf.CIQ(G$3,$B$1,$H$2,$A7,"L",,"USD","H")} -> 15171 | N7: {=_xll.ciqfunctions.udf.CIQ(B$3,$N$1,$B$2,$A7,"L",,"USD","H")} -> -3.1288 | O7: {=_xll.ciqfunctions.udf.CIQ(C$3,$N$1,$B$2,$A7,"L",,"USD","H")} -> -1.5265 | P7: {=_xll.ciqfunctions.udf.CIQ(D$3,$N$1,$B$2,$A7,"L",,"USD","H")} -> 8.5666 | Q7: {=_xll.ciqfunctions.udf.CIQ(E$3,$N$1,$B$2,$A7,"L",,"USD","H")} -> -6.3707 | R7: {=_xll.ciqfunctions.udf.CIQ(F$3,$N$1,$B$2,$A7,"L",,"USD","H")} -> -12.9156 | S7: {=_xll.ciqfunctions.udf.CIQ(G$3,$N$1,$B$2,$A7,"L",,"USD","H")} -> 17.6422 | T7: {=_xll.ciqfunctions.udf.CIQ(N$3,$N$1,$T$2,$A7,"L",,"USD","H")} -> -2.4387 | U7: {=_xll.ciqfunctions.udf.CIQ(O$3,$N$1,$T$2,$A7,"L",,"USD","H")} -> 1.1593 | V7: {=_xll.ciqfunctions.udf.CIQ(P$3,$N$1,$T$2,$A7,"L",,"USD","H")} -> 0.3947 | W7: {=_xll.ciqfunctions.udf.CIQ(Q$3,$N$1,$T$2,$A7,"L",,"USD","H")} -> 0.8808 | X7: {=_xll.ciqfunctions.udf.CIQ(R$3,$N$1,$T$2,$A7,"L",,"USD","H")} -> -10.0624 | Y7: {=_xll.ciqfunctions.udf.CIQ(S$3,$N$1,$T$2,$A7,"L",,"USD","H")} -> 5.1569 | Z7: {=_xll.ciqfunctions.udf.CIQ(B$3,$Z$1,$B$2,$A7,"L",,"USD","H")} -> 2306 | AA7: {=_xll.ciqfunctions.udf.CIQ(C$3,$Z$1,$B$2,$A7,"L",,"USD","H")} -> 7610 | AB7: {=_xll.ciqfunctions.udf.CIQ(D$3,$Z$1,$B$2,$A7,"L",,"USD","H")} -> 3239 | AC7: {=_xll.ciqfunctions.udf.CIQ(E$3,$Z$1,$B$2,$A7,"L",,"USD","H")} -> 1251 | AD7: {=_xll.ciqfunctions.udf.CIQ(F$3,$Z$1,$B$2,$A7,"L",,"USD","H")} -> -1959 | AE7: {=_xll.ciqfunctions.udf.CIQ(G$3,$Z$1,$B$2,$A7,"L",,"USD","H")} -> 639 | AF7: {=_xll.ciqfunctions.udf.CIQ(B$3,$Z$1,$H$2,$A7,"L",,"USD","H")} -> 9245 | AG7: {=_xll.ciqfunctions.udf.CIQ(C$3,$Z$1,$H$2,$A7,"L",,"USD","H")} -> 33680 | AH7: {=_xll.ciqfunctions.udf.CIQ(D$3,$Z$1,$H$2,$A7,"L",,"USD","H")} -> 17661 | AI7: {=_xll.ciqfunctions.udf.CIQ(E$3,$Z$1,$H$2,$A7,"L",,"USD","H")} -> 6403 | AJ7: {=_xll.ciqfunctions.udf.CIQ(F$3,$Z$1,$H$2,$A7,"L",,"USD","H")} -> 381 | AK7: {=_xll.ciqfunctions.udf.CIQ(G$3,$Z$1,$H$2,$A7,"L",,"USD","H")} -> 2891 | AL7: {=_xll.ciqfunctions.udf.CIQ(B$3,$AL$1,$AL$2,$A7,"L",,"USD","H")} -> -23.3123 | AM7: {=_xll.ciqfunctions.udf.CIQ(C$3,$AL$1,$AL$2,$A7,"L",,"USD","H")} -> -0.2622 | AN7: {=_xll.ciqfunctions.udf.CIQ(D$3,$AL$1,$AL$2,$A7,"L",,"USD","H")} -> 43.382 | AO7: {=_xll.ciqfunctions.udf.CIQ(E$3,$AL$1,$AL$2,$A7,"L",,"USD","H")} -> -37.0725 | AP7: {=_xll.ciqfunctions.udf.CIQ(F$3,$AL$1,$AL$2,$A7,"L",,"USD","H")} -> NM | AQ7: {=_xll.ciqfunctions.udf.CIQ(G$3,$AL$1,$AL$2,$A7,"L",,"USD","H")} -> -44.5313 | AR7: {=_xll.ciqfunctions.udf.CIQ(B$3,$AL$1,$AR$2,$A7,"L",,"USD","H")} -> -15.6248 | AS7: {=_xll.ciqfunctions.udf.CIQ(C$3,$AL$1,$AR$2,$A7,"L",,"USD","H")} -> -6.4705 | AT7: {=_xll.ciqfunctions.udf.CIQ(D$3,$AL$1,$AR$2,$A7,"L",,"USD","H")} -> -17.3523 | AU7: {=_xll.ciqfunctions.udf.CIQ(E$3,$AL$1,$AR$2,$A7,"L",,"USD","H")} -> -15.6835 | AV7: {=_xll.ciqfunctions.udf.CIQ(F$3,$AL$1,$AR$2,$A7,"L",,"USD","H")} -> -97.4999 | AW7: {=_xll.ciqfunctions.udf.CIQ(G$3,$AL$1,$AR$2,$A7,"L",,"USD","H")} -> -22.845 | AX7: {=_xll.ciqfunctions.udf.CIQ(B$3,$AX$1,$AX$2,$A7,"L",,"USD","H")} -> 6524 | AY7: {=_xll.ciqfunctions.udf.CIQ(C$3,$AX$1,$AX$2,$A7,"L",,"USD","H")} -> 15648 | AZ7: {=_xll.ciqfunctions.udf.CIQ(D$3,$AX$1,$AX$2,$A7,"L",,"USD","H")} -> 10074 | BA7: {=_xll.ciqfunctions.udf.CIQ(E$3,$AX$1,$AX$2,$A7,"L",,"USD","H")} -> 2910 | BB7: {=_xll.ciqfunctions.udf.CIQ(F$3,$AX$1,$AX$2,$A7,"L",,"USD","H")} -> 1263 | BC7: {=_xll.ciqfunctions.udf.CIQ(G$3,$AX$1,$AX$2,$A7,"L",,"USD","H")} -> 1939 | BD7: {=_xll.ciqfunctions.udf.CIQ(B$3,$AX$1,$BD$2,$A7,"L",,"USD","H")} -> 24308 | BE7: {=_xll.ciqfunctions.udf.CIQ(C$3,$AX$1,$BD$2,$A7,"L",,"USD","H")} -> 64294 | BF7: {=_xll.ciqfunctions.udf.CIQ(D$3,$AX$1,$BD$2,$A7,"L",,"USD","H")} -> 40081 | BG7: {=_xll.ciqfunctions.udf.CIQ(E$3,$AX$1,$BD$2,$A7,"L",,"USD","H")} -> 12565 | BH7: {=_xll.ciqfunctions.udf.CIQ(F$3,$AX$1,$BD$2,$A7,"L",,"USD","H")} -> 26961 | BI7: {=_xll.ciqfunctions.udf.CIQ(G$3,$AX$1,$BD$2,$A7,"L",,"USD","H")} -> 7389 | BJ7: =AX7/AX11-1 -> -0.0207145 | BK7: =AY7/AY11-1 -> -0.12819656 | BL7: =AZ7/AZ11-1 -> 0.12735004 | BM7: =BA7/BA11-1 -> -0.17164816 | BN7: =BB7/BB11-1 -> -0.78932444 | BO7: =BC7/BC11-1 -> -0.1072744 | BP7: =BD7/BD11-1 -> -0.017977619 | BQ7: =BE7/BE11-1 -> -0.031074809 | ... BU7: =BI7/BI11-1 -> -0.012693747 | BV7: {=_xll.ciqfunctions.udf.CIQ(B$3,$BV$1,$BV$2,$A7,"L",,"USD","H")/100} -> 0.071192 | BW7: {=_xll.ciqfunctions.udf.CIQ(C$3,$BV$1,$BV$2,$A7,"L",,"USD","H")/100} -> 0.04062 | BX7: {=_xll.ciqfunctions.udf.CIQ(D$3,$BV$1,$BV$2,$A7,"L",,"USD","H")/100} -> 0.0077 | BY7: {=_xll.ciqfunctions.udf.CIQ(E$3,$BV$1,$BV$2,$A7,"L",,"USD","H")/100} -> 0.08624 | BZ7: {=_xll.ciqfunctions.udf.CIQ(F$3,$BV$1,$BV$2,$A7,"L",,"USD","H")/100} -> -0.052536 | CA7: {=_xll.ciqfunctions.udf.CIQ(G$3,$BV$1,$BV$2,$A7,"L",,"USD","H")/100} -> 0.083172 | CB7: {=_xll.ciqfunctions.udf.CIQ(B$3,$BV$1,$CB$2,$A7,"L",,"USD","H")/100} -> 0.070402 | CC7: {=_xll.ciqfunctions.udf.CIQ(C$3,$BV$1,$CB$2,$A7,"L",,"USD","H")/100} -> 0.058622 | CD7: {=_xll.ciqfunctions.udf.CIQ(D$3,$BV$1,$CB$2,$A7,"L",,"USD","H")/100} -> 0.03161 | CE7: {=_xll.ciqfunctions.udf.CIQ(E$3,$BV$1,$CB$2,$A7,"L",,"USD","H")/100} -> 0.126879 | CF7: {=_xll.ciqfunctions.udf.CIQ(F$3,$BV$1,$CB$2,$A7,"L",,"USD","H")/100} -> -0.030975 | CG7: {=_xll.ciqfunctions.udf.CIQ(G$3,$BV$1,$CB$2,$A7,"L",,"USD","H")/100} -> 0.091608
A8: =EDATE(A4,-12) -> 45565 | B8: {=_xll.ciqfunctions.udf.CIQ(B$3,$B$1,$B$2,$A8,"L",,"USD","H")} -> 13482 | C8: {=_xll.ciqfunctions.udf.CIQ(C$3,$B$1,$B$2,$A8,"L",,"USD","H")} -> 87792 | D8: {=_xll.ciqfunctions.udf.CIQ(D$3,$B$1,$B$2,$A8,"L",,"USD","H")} -> 49416 | E8: {=_xll.ciqfunctions.udf.CIQ(E$3,$B$1,$B$2,$A8,"L",,"USD","H")} -> 5893 | F8: {=_xll.ciqfunctions.udf.CIQ(F$3,$B$1,$B$2,$A8,"L",,"USD","H")} -> 47223 | G8: {=_xll.ciqfunctions.udf.CIQ(G$3,$B$1,$B$2,$A8,"L",,"USD","H")} -> 3797 | H8: {=_xll.ciqfunctions.udf.CIQ(B$3,$B$1,$H$2,$A8,"L",,"USD","H")} -> 56924 | I8: {=_xll.ciqfunctions.udf.CIQ(C$3,$B$1,$H$2,$A8,"L",,"USD","H")} -> 341845 | J8: {=_xll.ciqfunctions.udf.CIQ(D$3,$B$1,$H$2,$A8,"L",,"USD","H")} -> 191689 | K8: {=_xll.ciqfunctions.udf.CIQ(E$3,$B$1,$H$2,$A8,"L",,"USD","H")} -> 23864 | L8: {=_xll.ciqfunctions.udf.CIQ(F$3,$B$1,$H$2,$A8,"L",,"USD","H")} -> 193929 | M8: {=_xll.ciqfunctions.udf.CIQ(G$3,$B$1,$H$2,$A8,"L",,"USD","H")} -> 14529 | N8: {=_xll.ciqfunctions.udf.CIQ(B$3,$N$1,$B$2,$A8,"L",,"USD","H")} -> -7.8973 | O8: {=_xll.ciqfunctions.udf.CIQ(C$3,$N$1,$B$2,$A8,"L",,"USD","H")} -> -0.8785 | P8: {=_xll.ciqfunctions.udf.CIQ(D$3,$N$1,$B$2,$A8,"L",,"USD","H")} -> -6.3648 | Q8: {=_xll.ciqfunctions.udf.CIQ(E$3,$N$1,$B$2,$A8,"L",,"USD","H")} -> -3.929 | R8: {=_xll.ciqfunctions.udf.CIQ(F$3,$N$1,$B$2,$A8,"L",,"USD","H")} -> -11.2734 | S8: {=_xll.ciqfunctions.udf.CIQ(G$3,$N$1,$B$2,$A8,"L",,"USD","H")} -> -5.7817 | T8: {=_xll.ciqfunctions.udf.CIQ(N$3,$N$1,$T$2,$A8,"L",,"USD","H")} -> -7.9481 | U8: {=_xll.ciqfunctions.udf.CIQ(O$3,$N$1,$T$2,$A8,"L",,"USD","H")} -> -1.4285 | V8: {=_xll.ciqfunctions.udf.CIQ(P$3,$N$1,$T$2,$A8,"L",,"USD","H")} -> -5.6022 | W8: {=_xll.ciqfunctions.udf.CIQ(Q$3,$N$1,$T$2,$A8,"L",,"USD","H")} -> 0.5774 | X8: {=_xll.ciqfunctions.udf.CIQ(R$3,$N$1,$T$2,$A8,"L",,"USD","H")} -> -14.339 | Y8: {=_xll.ciqfunctions.udf.CIQ(S$3,$N$1,$T$2,$A8,"L",,"USD","H")} -> -2.6859 | Z8: {=_xll.ciqfunctions.udf.CIQ(B$3,$Z$1,$B$2,$A8,"L",,"USD","H")} -> 2059 | AA8: {=_xll.ciqfunctions.udf.CIQ(C$3,$Z$1,$B$2,$A8,"L",,"USD","H")} -> 8610 | AB8: {=_xll.ciqfunctions.udf.CIQ(D$3,$Z$1,$B$2,$A8,"L",,"USD","H")} -> 4487 | AC8: {=_xll.ciqfunctions.udf.CIQ(E$3,$Z$1,$B$2,$A8,"L",,"USD","H")} -> 1673 | AD8: {=_xll.ciqfunctions.udf.CIQ(F$3,$Z$1,$B$2,$A8,"L",,"USD","H")} -> 206 | AE8: {=_xll.ciqfunctions.udf.CIQ(G$3,$Z$1,$B$2,$A8,"L",,"USD","H")} -> 812 | AF8: {=_xll.ciqfunctions.udf.CIQ(B$3,$Z$1,$H$2,$A8,"L",,"USD","H")} -> 9946 | AG8: {=_xll.ciqfunctions.udf.CIQ(C$3,$Z$1,$H$2,$A8,"L",,"USD","H")} -> 33700 | AH8: {=_xll.ciqfunctions.udf.CIQ(D$3,$Z$1,$H$2,$A8,"L",,"USD","H")} -> 16681 | AI8: {=_xll.ciqfunctions.udf.CIQ(E$3,$Z$1,$H$2,$A8,"L",,"USD","H")} -> 7140 | AJ8: {=_xll.ciqfunctions.udf.CIQ(F$3,$Z$1,$H$2,$A8,"L",,"USD","H")} -> 2711 | AK8: {=_xll.ciqfunctions.udf.CIQ(G$3,$Z$1,$H$2,$A8,"L",,"USD","H")} -> 3404 | AL8: {=_xll.ciqfunctions.udf.CIQ(B$3,$AL$1,$AL$2,$A8,"L",,"USD","H")} -> -26.4118 | AM8: {=_xll.ciqfunctions.udf.CIQ(C$3,$AL$1,$AL$2,$A8,"L",,"USD","H")} -> -5.0717 | AN8: {=_xll.ciqfunctions.udf.CIQ(D$3,$AL$1,$AL$2,$A8,"L",,"USD","H")} -> -31.2443 | AO8: {=_xll.ciqfunctions.udf.CIQ(E$3,$AL$1,$AL$2,$A8,"L",,"USD","H")} -> -17.5863 | AP8: {=_xll.ciqfunctions.udf.CIQ(F$3,$AL$1,$AL$2,$A8,"L",,"USD","H")} -> -95.7596 | AQ8: {=_xll.ciqfunctions.udf.CIQ(G$3,$AL$1,$AL$2,$A8,"L",,"USD","H")} -> -10.7693 | AR8: {=_xll.ciqfunctions.udf.CIQ(B$3,$AL$1,$AR$2,$A8,"L",,"USD","H")} -> -11.1885 | AS8: {=_xll.ciqfunctions.udf.CIQ(C$3,$AL$1,$AR$2,$A8,"L",,"USD","H")} -> -18.0647 | AT8: {=_xll.ciqfunctions.udf.CIQ(D$3,$AL$1,$AR$2,$A8,"L",,"USD","H")} -> -34.4893 | AU8: {=_xll.ciqfunctions.udf.CIQ(E$3,$AL$1,$AR$2,$A8,"L",,"USD","H")} -> -9.4254 | AV8: {=_xll.ciqfunctions.udf.CIQ(F$3,$AL$1,$AR$2,$A8,"L",,"USD","H")} -> -89.4395 | AW8: {=_xll.ciqfunctions.udf.CIQ(G$3,$AL$1,$AR$2,$A8,"L",,"USD","H")} -> -10.3267 | AX8: {=_xll.ciqfunctions.udf.CIQ(B$3,$AX$1,$AX$2,$A8,"L",,"USD","H")} -> 5663 | AY8: {=_xll.ciqfunctions.udf.CIQ(C$3,$AX$1,$AX$2,$A8,"L",,"USD","H")} -> 17267 | AZ8: {=_xll.ciqfunctions.udf.CIQ(D$3,$AX$1,$AX$2,$A8,"L",,"USD","H")} -> 9606 | BA8: {=_xll.ciqfunctions.udf.CIQ(E$3,$AX$1,$AX$2,$A8,"L",,"USD","H")} -> 3142 | BB8: {=_xll.ciqfunctions.udf.CIQ(F$3,$AX$1,$AX$2,$A8,"L",,"USD","H")} -> 8130 | BC8: {=_xll.ciqfunctions.udf.CIQ(G$3,$AX$1,$AX$2,$A8,"L",,"USD","H")} -> 1946 | BD8: {=_xll.ciqfunctions.udf.CIQ(B$3,$AX$1,$BD$2,$A8,"L",,"USD","H")} -> 24446 | BE8: {=_xll.ciqfunctions.udf.CIQ(C$3,$AX$1,$BD$2,$A8,"L",,"USD","H")} -> 66595 | BF8: {=_xll.ciqfunctions.udf.CIQ(D$3,$AX$1,$BD$2,$A8,"L",,"USD","H")} -> 38943 | BG8: {=_xll.ciqfunctions.udf.CIQ(E$3,$AX$1,$BD$2,$A8,"L",,"USD","H")} -> 13168 | BH8: {=_xll.ciqfunctions.udf.CIQ(F$3,$AX$1,$BD$2,$A8,"L",,"USD","H")} -> 31693 | BI8: {=_xll.ciqfunctions.udf.CIQ(G$3,$AX$1,$BD$2,$A8,"L",,"USD","H")} -> 7612 | BJ8: =AX8/AX12-1 -> -0.091885824 | BK8: =AY8/AY12-1 -> 0.072950972 | BL8: =AZ8/AZ12-1 -> -0.16931857 | BM8: =BA8/BA12-1 -> -0.09556707 | BN8: =BB8/BB12-1 -> -0.3634513 | BO8: =BC8/BC12-1 -> 0.078116343 | BP8: =BD8/BD12-1 -> -0.040656149 | BQ8: =BE8/BE12-1 -> 0.12802141 | ... BU8: =BI8/BI12-1 -> 0.013446944 | BV8: {=_xll.ciqfunctions.udf.CIQ(B$3,$BV$1,$BV$2,$A8,"L",,"USD","H")/100} -> 0.067448 | BW8: {=_xll.ciqfunctions.udf.CIQ(C$3,$BV$1,$BV$2,$A8,"L",,"USD","H")/100} -> 0.05476 | BX8: {=_xll.ciqfunctions.udf.CIQ(D$3,$BV$1,$BV$2,$A8,"L",,"USD","H")/100} -> 0.033936 | BY8: {=_xll.ciqfunctions.udf.CIQ(E$3,$BV$1,$BV$2,$A8,"L",,"USD","H")/100} -> 0.136252 | BZ8: {=_xll.ciqfunctions.udf.CIQ(F$3,$BV$1,$BV$2,$A8,"L",,"USD","H")/100} -> -0.029452 | CA8: {=_xll.ciqfunctions.udf.CIQ(G$3,$BV$1,$BV$2,$A8,"L",,"USD","H")/100} -> 0.100516 | CB8: {=_xll.ciqfunctions.udf.CIQ(B$3,$BV$1,$CB$2,$A8,"L",,"USD","H")/100} -> 0.085767 | CC8: {=_xll.ciqfunctions.udf.CIQ(C$3,$BV$1,$CB$2,$A8,"L",,"USD","H")/100} -> 0.061747 | CD8: {=_xll.ciqfunctions.udf.CIQ(D$3,$BV$1,$CB$2,$A8,"L",,"USD","H")/100} -> 0.026823 | CE8: {=_xll.ciqfunctions.udf.CIQ(E$3,$BV$1,$CB$2,$A8,"L",,"USD","H")/100} -> 0.11076 | CF8: {=_xll.ciqfunctions.udf.CIQ(F$3,$BV$1,$CB$2,$A8,"L",,"USD","H")/100} -> -0.015098 | CG8: {=_xll.ciqfunctions.udf.CIQ(G$3,$BV$1,$CB$2,$A8,"L",,"USD","H")/100} -> 0.101028
A9: =EDATE(A5,-12) -> 45473 | B9: {=_xll.ciqfunctions.udf.CIQ(B$3,$B$1,$B$2,$A9,"L",,"USD","H")} -> 14023 | C9: {=_xll.ciqfunctions.udf.CIQ(C$3,$B$1,$B$2,$A9,"L",,"USD","H")} -> 89986 | D9: {=_xll.ciqfunctions.udf.CIQ(D$3,$B$1,$B$2,$A9,"L",,"USD","H")} -> 49778 | E9: {=_xll.ciqfunctions.udf.CIQ(E$3,$B$1,$B$2,$A9,"L",,"USD","H")} -> 6052 | F9: {=_xll.ciqfunctions.udf.CIQ(F$3,$B$1,$B$2,$A9,"L",,"USD","H")} -> 47610 | G9: {=_xll.ciqfunctions.udf.CIQ(G$3,$B$1,$B$2,$A9,"L",,"USD","H")} -> 3715 | H9: {=_xll.ciqfunctions.udf.CIQ(B$3,$B$1,$H$2,$A9,"L",,"USD","H")} -> 58080 | I9: {=_xll.ciqfunctions.udf.CIQ(C$3,$B$1,$H$2,$A9,"L",,"USD","H")} -> 342623 | J9: {=_xll.ciqfunctions.udf.CIQ(D$3,$B$1,$H$2,$A9,"L",,"USD","H")} -> 195048 | K9: {=_xll.ciqfunctions.udf.CIQ(E$3,$B$1,$H$2,$A9,"L",,"USD","H")} -> 24105 | L9: {=_xll.ciqfunctions.udf.CIQ(F$3,$B$1,$H$2,$A9,"L",,"USD","H")} -> 199929 | M9: {=_xll.ciqfunctions.udf.CIQ(G$3,$B$1,$H$2,$A9,"L",,"USD","H")} -> 14762 | N9: {=_xll.ciqfunctions.udf.CIQ(B$3,$N$1,$B$2,$A9,"L",,"USD","H")} -> 9.8722 | O9: {=_xll.ciqfunctions.udf.CIQ(C$3,$N$1,$B$2,$A9,"L",,"USD","H")} -> 12.1237 | P9: {=_xll.ciqfunctions.udf.CIQ(D$3,$N$1,$B$2,$A9,"L",,"USD","H")} -> 4.723 | Q9: {=_xll.ciqfunctions.udf.CIQ(E$3,$N$1,$B$2,$A9,"L",,"USD","H")} -> 10.4178 | R9: {=_xll.ciqfunctions.udf.CIQ(F$3,$N$1,$B$2,$A9,"L",,"USD","H")} -> -2.3585 | S9: {=_xll.ciqfunctions.udf.CIQ(G$3,$N$1,$B$2,$A9,"L",,"USD","H")} -> 11.2608 | T9: {=_xll.ciqfunctions.udf.CIQ(N$3,$N$1,$T$2,$A9,"L",,"USD","H")} -> -15.5508 | U9: {=_xll.ciqfunctions.udf.CIQ(O$3,$N$1,$T$2,$A9,"L",,"USD","H")} -> -6.302 | V9: {=_xll.ciqfunctions.udf.CIQ(P$3,$N$1,$T$2,$A9,"L",,"USD","H")} -> -9.083 | W9: {=_xll.ciqfunctions.udf.CIQ(Q$3,$N$1,$T$2,$A9,"L",,"USD","H")} -> -4.4401 | X9: {=_xll.ciqfunctions.udf.CIQ(R$3,$N$1,$T$2,$A9,"L",,"USD","H")} -> -12.1346 | Y9: {=_xll.ciqfunctions.udf.CIQ(S$3,$N$1,$T$2,$A9,"L",,"USD","H")} -> -8.2194 | Z9: {=_xll.ciqfunctions.udf.CIQ(B$3,$Z$1,$B$2,$A9,"L",,"USD","H")} -> 2329 | AA9: {=_xll.ciqfunctions.udf.CIQ(C$3,$Z$1,$B$2,$A9,"L",,"USD","H")} -> 9240 | AB9: {=_xll.ciqfunctions.udf.CIQ(D$3,$Z$1,$B$2,$A9,"L",,"USD","H")} -> 4434 | AC9: {=_xll.ciqfunctions.udf.CIQ(E$3,$Z$1,$B$2,$A9,"L",,"USD","H")} -> 1690 | AD9: {=_xll.ciqfunctions.udf.CIQ(F$3,$Z$1,$B$2,$A9,"L",,"USD","H")} -> -129 | AE9: {=_xll.ciqfunctions.udf.CIQ(G$3,$Z$1,$B$2,$A9,"L",,"USD","H")} -> 844 | AF9: {=_xll.ciqfunctions.udf.CIQ(B$3,$Z$1,$H$2,$A9,"L",,"USD","H")} -> 10685 | AG9: {=_xll.ciqfunctions.udf.CIQ(C$3,$Z$1,$H$2,$A9,"L",,"USD","H")} -> 34160 | AH9: {=_xll.ciqfunctions.udf.CIQ(D$3,$Z$1,$H$2,$A9,"L",,"USD","H")} -> 18720 | AI9: {=_xll.ciqfunctions.udf.CIQ(E$3,$Z$1,$H$2,$A9,"L",,"USD","H")} -> 7497 | AJ9: {=_xll.ciqfunctions.udf.CIQ(F$3,$Z$1,$H$2,$A9,"L",,"USD","H")} -> 7363 | AK9: {=_xll.ciqfunctions.udf.CIQ(G$3,$Z$1,$H$2,$A9,"L",,"USD","H")} -> 3502 | AL9: {=_xll.ciqfunctions.udf.CIQ(B$3,$AL$1,$AL$2,$A9,"L",,"USD","H")} -> 4.3458 | AM9: {=_xll.ciqfunctions.udf.CIQ(C$3,$AL$1,$AL$2,$A9,"L",,"USD","H")} -> 17.2588 | AN9: {=_xll.ciqfunctions.udf.CIQ(D$3,$AL$1,$AL$2,$A9,"L",,"USD","H")} -> -26.223 | AO9: {=_xll.ciqfunctions.udf.CIQ(E$3,$AL$1,$AL$2,$A9,"L",,"USD","H")} -> 8.8216 | AP9: {=_xll.ciqfunctions.udf.CIQ(F$3,$AL$1,$AL$2,$A9,"L",,"USD","H")} -> NM | AQ9: {=_xll.ciqfunctions.udf.CIQ(G$3,$AL$1,$AL$2,$A9,"L",,"USD","H")} -> 22.3188 | AR9: {=_xll.ciqfunctions.udf.CIQ(B$3,$AL$1,$AR$2,$A9,"L",,"USD","H")} -> -17.35 | AS9: {=_xll.ciqfunctions.udf.CIQ(C$3,$AL$1,$AR$2,$A9,"L",,"USD","H")} -> -33.9521 | AT9: {=_xll.ciqfunctions.udf.CIQ(D$3,$AL$1,$AR$2,$A9,"L",,"USD","H")} -> -37.9475 | AU9: {=_xll.ciqfunctions.udf.CIQ(E$3,$AL$1,$AR$2,$A9,"L",,"USD","H")} -> -13.8969 | AV9: {=_xll.ciqfunctions.udf.CIQ(F$3,$AL$1,$AR$2,$A9,"L",,"USD","H")} -> -60.5202 | AW9: {=_xll.ciqfunctions.udf.CIQ(G$3,$AL$1,$AR$2,$A9,"L",,"USD","H")} -> -26.7211 | AX9: {=_xll.ciqfunctions.udf.CIQ(B$3,$AX$1,$AX$2,$A9,"L",,"USD","H")} -> 6125 | AY9: {=_xll.ciqfunctions.udf.CIQ(C$3,$AX$1,$AX$2,$A9,"L",,"USD","H")} -> 16649 | AZ9: {=_xll.ciqfunctions.udf.CIQ(D$3,$AX$1,$AX$2,$A9,"L",,"USD","H")} -> 9758 | BA9: {=_xll.ciqfunctions.udf.CIQ(E$3,$AX$1,$AX$2,$A9,"L",,"USD","H")} -> 3175 | BB9: {=_xll.ciqfunctions.udf.CIQ(F$3,$AX$1,$AX$2,$A9,"L",,"USD","H")} -> 7848 | BC9: {=_xll.ciqfunctions.udf.CIQ(G$3,$AX$1,$AX$2,$A9,"L",,"USD","H")} -> 1927 | BD9: {=_xll.ciqfunctions.udf.CIQ(B$3,$AX$1,$BD$2,$A9,"L",,"USD","H")} -> 25019 | BE9: {=_xll.ciqfunctions.udf.CIQ(C$3,$AX$1,$BD$2,$A9,"L",,"USD","H")} -> 65421 | BF9: {=_xll.ciqfunctions.udf.CIQ(D$3,$AX$1,$BD$2,$A9,"L",,"USD","H")} -> 40901 | BG9: {=_xll.ciqfunctions.udf.CIQ(E$3,$AX$1,$BD$2,$A9,"L",,"USD","H")} -> 13500 | BH9: {=_xll.ciqfunctions.udf.CIQ(F$3,$AX$1,$BD$2,$A9,"L",,"USD","H")} -> 36335 | BI9: {=_xll.ciqfunctions.udf.CIQ(G$3,$AX$1,$BD$2,$A9,"L",,"USD","H")} -> 7471 | BJ9: =AX9/AX13-1 -> 0.1357315 | BK9: =AY9/AY13-1 -> 0.23426496 | BL9: =AZ9/AZ13-1 -> -0.034339436 | BM9: =BA9/BA13-1 -> 0.10243056 | BN9: =BB9/BB13-1 -> -0.17666807 | BO9: =BC9/BC13-1 -> 0.20739348 | BP9: =BD9/BD13-1 -> -0.12609592 | BQ9: =BE9/BE13-1 -> -0.14959248 | ... BU9: =BI9/BI13-1 -> -0.15352368 | BV9: {=_xll.ciqfunctions.udf.CIQ(B$3,$BV$1,$BV$2,$A9,"L",,"USD","H")/100} -> 0.083272 | BW9: {=_xll.ciqfunctions.udf.CIQ(C$3,$BV$1,$BV$2,$A9,"L",,"USD","H")/100} -> 0.069184 | BX9: {=_xll.ciqfunctions.udf.CIQ(D$3,$BV$1,$BV$2,$A9,"L",,"USD","H")/100} -> 0.03174 | BY9: {=_xll.ciqfunctions.udf.CIQ(E$3,$BV$1,$BV$2,$A9,"L",,"USD","H")/100} -> 0.141836 | BZ9: {=_xll.ciqfunctions.udf.CIQ(F$3,$BV$1,$BV$2,$A9,"L",,"USD","H")/100} -> -0.003476 | CA9: {=_xll.ciqfunctions.udf.CIQ(G$3,$BV$1,$BV$2,$A9,"L",,"USD","H")/100} -> 0.130536 | CB9: {=_xll.ciqfunctions.udf.CIQ(B$3,$BV$1,$CB$2,$A9,"L",,"USD","H")/100} -> 0.092388 | CC9: {=_xll.ciqfunctions.udf.CIQ(C$3,$BV$1,$CB$2,$A9,"L",,"USD","H")/100} -> 0.065376 | CD9: {=_xll.ciqfunctions.udf.CIQ(D$3,$BV$1,$CB$2,$A9,"L",,"USD","H")/100} -> 0.038862 | CE9: {=_xll.ciqfunctions.udf.CIQ(E$3,$BV$1,$CB$2,$A9,"L",,"USD","H")/100} -> 0.118309 | CF9: {=_xll.ciqfunctions.udf.CIQ(F$3,$BV$1,$CB$2,$A9,"L",,"USD","H")/100} -> 0.017363 | CG9: {=_xll.ciqfunctions.udf.CIQ(G$3,$BV$1,$CB$2,$A9,"L",,"USD","H")/100} -> 0.117466
